Workbook
Name Breaker: 'Assumptions '!$C$9
Name Breaker: '[1]Income Statement'!#REF!
Name Breaker: '[2]Income Statement'!#REF!
Name Breaker: #REF!
Name Days: '[1]WC Schedule'!$C$30
Name Days: '[2]WC Schedule'!$C$28
Name Days: 'WC Schedule'!$C$29

Sheet Assumptions 
B2: ="Three-Statement Model for " &C5 -> Three-Statement Model for CROCS, INC.
B3: ="(Dollars in "&IF('Assumptions '!C8=0,"Thousands","Millions")& " Except Per Share Data)" -> (Dollars in Thousands Except Per Share Data)
B5: Company Name | C5: CROCS, INC.
B6: Ticker | C6: CROX
B7: Last Year of Audited Financials | C7: 2024
B8: Financial Format (0 = Thousands, 1= Millions) | C8: 0
B9: Breaker | C9: On
B10: Income Statement Assumptions
D12: =C7+1 -> 2025 | E12: =D12+1 -> 2026 | F12: =E12+1 -> 2027 | G12: =F12+1 -> 2028 | H12: =G12+1 -> 2029 | I12: =H12+1 -> 2030
B13: Revenues
B14: Wholesale | D14: 0.01 | E14: 0.01 | F14: 0.01 | G14: 0.01 | H14: 0.01 | I14: 0.01
B15: Direct To Customers | D15: 0.02 | E15: 0.02 | F15: 0.02 | G15: 0.02 | H15: 0.02 | I15: 0.02
B17: Cost of Sales
B18: As a % of Revenue | D18: 0.45 | E18: 0.45 | F18: 0.45 | G18: 0.45 | H18: 0.45 | I18: 0.45
B19: Selling, General & Administration Expenses | D19: 0.32 | E19: 0.32 | F19: 0.32 | G19: 0.32 | H19: 0.32 | I19: 0.32
B20: Depreciation and Amortization & Impairment Gains (Losses), net | D20: See Fixed Asset Schedule
B21: Income from operations
B22: Foreign currency gains (losses), net | D22: -0.0004 | E22: -0.0004 | F22: -0.0004 | G22: -0.0004 | H22: -0.0004 | I22: -0.0004
B23: Interest Income | D23: See Debt Schedule
B24: Interest expense | D24: See Debt Schedule
B25: Other income (expense), net | D25: 0.0002 | E25: 0.0002 | F25: 0.0002 | G25: 0.0002 | H25: 0.0002 | I25: 0.0002
B26: Effective Tax Rate | D26: 0.21 | E26: 0.21 | F26: 0.21 | G26: 0.21 | H26: 0.21 | I26: 0.21
B27: Projected Shares Outstanding (unit in thousands) | D27: 60500 | E27: 60500 | F27: 60500 | G27: 60500 | H27: 60500 | I27: 60500
B30: Balance Sheet Assumptions
D32: =D12 -> 2025 | E32: =E12 -> 2026 | F32: =F12 -> 2027 | G32: =G12 -> 2028 | H32: =H12 -> 2029 | I32: =I12 -> 2030
B34: Assets (As a % of Total Revenues, except where noted)
B35: Cash and Cash Equivalents | D35: As per Schedule. See below for minimum requirements.
D36: As per Working capital Schedule
B37: Inventories (DAYS)
B38: Accounts receivable
B39: Prepaid expenses and other assets
B40: Income taxes receivable (% of revenue)
B41: Deferred tax assets, net (% of revenue)
B42: Restricted cash
B43: Net Property and Equipment | D43: See Fixed Asset Schedule
B44: Intangible assets, net | D44: 0.5 | E44: 0.5 | F44: 0.5 | G44: 0.5 | H44: 0.5 | I44: 0.5
B45: Other Non Current Assets | D45: 0.4 | E45: 0.4 | F45: 0.4 | G45: 0.4 | H45: 0.4 | I45: 0.4
B47: Liabilities (As a % of Total Revenues)
B48: Current Liabilities | D48: As per Working capital Schedule
B49: Accounts Payable (DAYS) | D49: As per Working Capital Schedule
...

Sheet Transaction Summary
B1: Crocs, Inc.
B6: KEY INPUT | F6: INITIAL VALUATION
H7: Enterprise value method
B8: Transaction date | C8: 46022
B9: Assumed exit date | C9: 47483 | F9: LTM EBITDA | H9: =C12 -> 957607.3 | I9: =_xlfn.FORMULATEXT(H9) -> =C12
B10: Pre-LBO diluted shares outstanding | C10: 59382 | F10: EV/ LTM EBITDA | H10: =H11/H9 -> 6.9631531 | I10: =_xlfn.FORMULATEXT(H10) -> =H11/H9
B11: % Pre-LBO diluted shares outstanding bought | C11: 1 | F11: Enterprise Value | H11: =H13+H15 -> 6667966.2 | I11: =_xlfn.FORMULATEXT(H11) -> =H13+H15
B12: LTM EBITDA | C12: ='Income Statement '!F18-'Income Statement '!F15 -> 957607.3 | D12: =_xlfn.FORMULATEXT(C12) -> ='Income Statement '!F18-'Income Statement '!F15
B13: Gross Debt at entry | C13: ='Balance Sheet '!F23+'Balance Sheet '!F28+'Balance Sheet '!F29 -> 1123938.1 | D13: =_xlfn.FORMULATEXT(C13) -> ='Balance Sheet '!F23+'Balance Sheet '!F28+'Balance Sheet '!F29 | F13: Less: Net Debt | H13: =C13-C14 -> 611714.77 | I13: =_xlfn.FORMULATEXT(H13) -> =C13-C14
B14: Cash at entry | C14: ='Balance Sheet '!F8 -> 512223.38 | D14: =_xlfn.FORMULATEXT(C14) -> ='Balance Sheet '!F8
F15: Offer Value (Equity Value) | H15: =H20*H16 -> 6056251.4 | I15: =_xlfn.FORMULATEXT(H15) -> =H20*H16
B16: New Debt/ LTM EBITDA | C16: 4 | F16: Diluted shares outstanding | H16: =C10 -> 59382 | I16: =_xlfn.FORMULATEXT(H16) -> =C10
B17: EV/ LTM EBITDA at exit | C17: =H10 -> 6.9631531 | D17: =_xlfn.FORMULATEXT(C17) -> =H10
F18: Share price as of last close | H18: 84.99
B19: Deal Fee (% of Offer Value) | C19: 0.005 | F19: Latest closing share price date | H19: 45931
B20: Deal Fee | C20: =C19*H15 -> 30281.257 | D20: =_xlfn.FORMULATEXT(C20) -> =C19*H15 | F20: Offer value per share | H20: =H18*(1+0.2) -> 101.988 | I20: =_xlfn.FORMULATEXT(H20) -> =H18*(1+0.2)
B22: Term of Loan | C22: 5
B23: Financing Fee (% of Borrowing) | C23: 0.005
B24: Financing Fee | C24: =C23*C38 -> 19152.146 | D24: =_xlfn.FORMULATEXT(C24) -> =C23*C38
B25: Annual Financing Fee Amortization | C25: =C24/C22 -> 3830.4292 | D25: =_xlfn.FORMULATEXT(C25) -> =C24/C22
B27: USE OF FUNDS
B29: Deal Fee | C29: =C20 -> 30281.257 | D29: =_xlfn.FORMULATEXT(C29) -> =C20
B30: Financing Fee | C30: =C24 -> 19152.146 | D30: =_xlfn.FORMULATEXT(C30) -> =C24
B31: Buyout of equity | C31: =H15 -> 6056251.4 | D31: =_xlfn.FORMULATEXT(C31) -> =H15
B32: Payoff of Oldco Debt | C32: =C13 -> 1123938.1 | D32: =_xlfn.FORMULATEXT(C32) -> =C13
B33: Total Uses | C33: =SUM(C29:C32) -> 7229623 | D33: =_xlfn.FORMULATEXT(C33) -> =SUM(C29:C32)
B35: SOURCES OF FUNDS
B37: Excess cash | C37: =C14 -> 512223.38 | D37: =_xlfn.FORMULATEXT(C37) -> =C14
B38: New term debt | C38: =C16*C12 -> 3830429.2 | D38: =_xlfn.FORMULATEXT(C38) -> =C16*C12
B39: Management rollover | C39: =C31*(1-C11) -> 0 | D39: =_xlfn.FORMULATEXT(C39) -> =C31*(1-C11)
B40: Sponser Equity | C40: =C41-SUM(C37:C39) -> 2886970.4 | D40: =_xlfn.FORMULATEXT(C40) -> =C41-SUM(C37:C39)
B41: Total Sources | C41: =C33 -> 7229623 | D41: =_xlfn.FORMULATEXT(C41) -> =C33
B44: OWNERSHIP SUMMARY
D45: % Ownership
B46: Management rollover | C46: =C39 -> 0 | D46: =C46/C48 -> 0 | E46: =_xlfn.FORMULATEXT(D46) -> =C46/C48
B47: Sponser Equity | C47: =C40 -> 2886970.4 | D47: =C47/C48 -> 1 | E47: =_xlfn.FORMULATEXT(D47) -> =C47/C48
B48: Total Equity | C48: =C46+C47 -> 2886970.4 | D48: =D46+D47 -> 1 | E48: =_xlfn.FORMULATEXT(D48) -> =D46+D47
B53: New Term Debt Repayment Terms:
B54: Mandatory paydown (% of original) | C54: =1/7 -> 0.14285714 | D54: =_xlfn.FORMULATEXT(C54) -> =1/7
B55: Mandatory paydown $ | C55: =C54*C38 -> 547204.17 | D55: =_xlfn.FORMULATEXT(C55) -> =C54*C38
...

Sheet Income Statement 
B2: ='Assumptions '!C5& " Consolidated Income Statement" -> CROCS, INC. Consolidated Income Statement
B3: ='Assumptions '!B3 -> (Dollars in Thousands Except Per Share Data)
C5: =D5-1 -> 2022 | D5: =E5-1 -> 2023 | E5: ='Assumptions '!C7 -> 2024 | F5: ='Assumptions '!D12 -> 2025 | G5: ='Assumptions '!E12 -> 2026 | H5: ='Assumptions '!F12 -> 2027 | I5: ='Assumptions '!G12 -> 2028 | J5: ='Assumptions '!H12 -> 2029
B6: Revenues
B7: Wholesale | C7: 1951442 | D7: 2060474 | E7: 2064018 | F7: =E7*('Assumptions '!D14+1) -> 2084658.2 | G7: =F7*('Assumptions '!E14+1) -> 2105504.8 | H7: =G7*('Assumptions '!F14+1) -> 2126559.8 | I7: =H7*('Assumptions '!G14+1) -> 2147825.4 | J7: =I7*('Assumptions '!H14+1) -> 2169303.7
B8: Direct To Customers | C8: 1603543 | D8: 1901873 | E8: 2038090 | F8: =E8*('Assumptions '!D15+1) -> 2078851.8 | G8: =F8*('Assumptions '!E15+1) -> 2120428.8 | H8: =G8*('Assumptions '!F15+1) -> 2162837.4 | I8: =H8*('Assumptions '!G15+1) -> 2206094.2 | J8: =I8*('Assumptions '!H15+1) -> 2250216
B9: Total Revenues | C9: =SUM(C7:C8) -> 3554985 | D9: =SUM(D7:D8) -> 3962347 | E9: =SUM(E7:E8) -> 4102108 | F9: =SUM(F7:F8) -> 4163510 | G9: =SUM(G7:G8) -> 4225933.6 | H9: =SUM(H7:H8) -> 4289397.2 | I9: =SUM(I7:I8) -> 4353919.6 | J9: =SUM(J7:J8) -> 4419519.7
B11: Cost of Sales | C11: -1694703 | D11: -1752337 | E11: -1691850 | F11: =-F9*'Assumptions '!D18 -> -1873579.5 | G11: =-G9*'Assumptions '!E18 -> -1901670.1 | H11: =-H9*'Assumptions '!F18 -> -1930228.7 | I11: =-I9*'Assumptions '!G18 -> -1959263.8 | J11: =-J9*'Assumptions '!H18 -> -1988783.9
B12: Gross Profit | C12: =C9+C11 -> 1860282 | D12: =D9+D11 -> 2210010 | E12: =E9+E11 -> 2410258 | F12: =F9+F11 -> 2289930.5 | G12: =G9+G11 -> 2324263.5 | H12: =H9+H11 -> 2359168.5 | I12: =I9+I11 -> 2394655.8 | J12: =J9+J11 -> 2430735.8
B13: Operating Costs
B14: ='Assumptions '!B19 -> Selling, General & Administration Expenses | C14: -982706 | D14: -1140812 | E14: -1341575 | F14: =-F9*'Assumptions '!D19 -> -1332323.2 | G14: =-G9*'Assumptions '!E19 -> -1352298.8 | H14: =-H9*'Assumptions '!F19 -> -1372607.1 | I14: =-I9*'Assumptions '!G19 -> -1393254.3 | J14: =-J9*'Assumptions '!H19 -> -1414246.3
B15: Depreciation and Amortization | C15: -26820 | D15: -32415 | E15: -46772 | F15: ='PPE Schedule'!H9 -> -57389.352 | G15: ='PPE Schedule'!I9 -> -64887.435 | H15: ='PPE Schedule'!J9 -> -73082.794 | I15: ='PPE Schedule'!K9 -> -81104.697 | J15: ='PPE Schedule'!L9 -> -89398.067
B16: Total Expenses | C16: =SUM(C14:C15) -> -1009526 | D16: =SUM(D14:D15) -> -1173227 | E16: =SUM(E14:E15) -> -1388347 | F16: =SUM(F14:F15) -> -1389712.5 | G16: =SUM(G14:G15) -> -1417186.2 | H16: =SUM(H14:H15) -> -1445689.9 | I16: =SUM(I14:I15) -> -1474359 | J16: =SUM(J14:J15) -> -1503644.4
B18: Operating Income (EBIT) | C18: =C12+C16 -> 850756 | D18: =D12+D16 -> 1036783 | E18: =E12+E16 -> 1021911 | F18: =F12+F16 -> 900217.94 | G18: =G12+G16 -> 907077.29 | H18: =H12+H16 -> 913478.57 | I18: =I12+I16 -> 920296.8 | J18: =J12+J16 -> 927091.47
B19: Foreign currency gains (losses), net | C19: 3228 | D19: -1240 | E19: -6777 | F19: =F9*'Assumptions '!D22 -> -1665.404 | G19: =G9*'Assumptions '!E22 -> -1690.3734 | H19: =H9*'Assumptions '!F22 -> -1715.7589 | I19: =I9*'Assumptions '!G22 -> -1741.5678 | J19: =J9*'Assumptions '!H22 -> -1767.8079
B20: Interest income | C20: 1020 | D20: 2406 | E20: 3484 | F20: =IFERROR(IF(Breaker="On", 0, 'Debt & Equity Schedule'!E67),0) -> 0 | G20: =IFERROR(IF(Breaker="On", 0, 'Debt & Equity Schedule'!F67),0) -> 0 | H20: =IFERROR(IF(Breaker="On", 0, 'Debt & Equity Schedule'!G67),0) -> 0 | I20: =IFERROR(IF(Breaker="On", 0, 'Debt & Equity Schedule'!H67),0) -> 0 | J20: =IFERROR(IF(Breaker="On", 0, 'Debt & Equity Schedule'!I67),0) -> 0
B21: Interest expense | C21: -136158 | D21: -161351 | E21: -109264 | F21: =IFERROR(IF(Breaker="On", 0, 'Debt & Equity Schedule'!E59),0) -> 0 | G21: =IFERROR(IF(Breaker="On", 0, 'Debt & Equity Schedule'!F59),0) -> 0 | H21: =IFERROR(IF(Breaker="On", 0, 'Debt & Equity Schedule'!G59),0) -> 0 | I21: =IFERROR(IF(Breaker="On", 0, 'Debt & Equity Schedule'!H59),0) -> 0 | J21: =IFERROR(IF(Breaker="On", 0, 'Debt & Equity Schedule'!I59),0) -> 0
B22: Other income (expense), net | C22: -338 | D22: -326 | E22: 1231 | F22: ='Assumptions '!D25*F9 -> 832.702 | G22: ='Assumptions '!E25*G9 -> 845.18672 | H22: ='Assumptions '!F25*H9 -> 857.87944 | I22: ='Assumptions '!G25*I9 -> 870.78391 | J22: ='Assumptions '!H25*J9 -> 883.90394
B23: Income before income taxes | C23: =SUM(C18:C22) -> 718508 | D23: =SUM(D18:D22) -> 876272 | E23: =SUM(E18:E22) -> 910585 | F23: =F18+F19+F22 -> 899385.24 | G23: =G18+G19+G22 -> 906232.11 | H23: =H18+H19+H22 -> 912620.69 | I23: =I18+I19+I22 -> 919426.02 | J23: =J18+J19+J22 -> 926207.56
B24: Income tax expense (benefit) | C24: 178349 | D24: 83706 | E24: -39486 | F24: =-F23*'Assumptions '!D26 -> -188870.9 | G24: =-G23*'Assumptions '!E26 -> -190308.74 | H24: =-H23*'Assumptions '!F26 -> -191650.34 | I24: =-I23*'Assumptions '!G26 -> -193079.46 | J24: =-J23*'Assumptions '!H26 -> -194503.59
B25: Net income | C25: =C23-C24 -> 540159 | D25: =D23-D24 -> 792566 | E25: =E23-E24 -> 950071 | F25: =F23-F24 -> 1088256.1 | G25: =G23-G24 -> 1096540.8 | H25: =H23-H24 -> 1104271 | I25: =I23-I24 -> 1112505.5 | J25: =J23-J24 -> 1120711.1

Sheet Return
B2: EXIT VALUATION
E5: Valuation at various exit EBITDA multiples
B6: EV/EBITDA multiple at exit | E6: =F6-0.5 -> 5.9631531 | F6: =G6-0.5 -> 6.4631531 | G6: ='Transaction Summary'!C17 -> 6.9631531 | H6: =G6+0.5 -> 7.4631531 | I6: =H6+0.5 -> 7.9631531
B7: EBITDA at exit | E7: ='Income Statement '!$J$18-'Income Statement '!$J$15 -> 1016489.5 | F7: ='Income Statement '!$J$18-'Income Statement '!$J$15 -> 1016489.5 | G7: ='Income Statement '!$J$18-'Income Statement '!$J$15 -> 1016489.5 | H7: ='Income Statement '!$J$18-'Income Statement '!$J$15 -> 1016489.5 | I7: ='Income Statement '!$J$18-'Income Statement '!$J$15 -> 1016489.5 | J7: =_xlfn.FORMULATEXT(E7) -> ='Income Statement '!$J$18-'Income Statement '!$J$15
B8: Enterprise value | E8: =E6*E7 -> 6061482.7 | F8: =F6*F7 -> 6569727.4 | G8: =G6*G7 -> 7077972.2 | H8: =H6*H7 -> 7586217 | I8: =I6*I7 -> 8094461.7 | J8: =_xlfn.FORMULATEXT(E8) -> =E6*E7
B9: Net debt:
B10: Revolver | E10: ='Balance Sheet '!$M$29 -> 0 | F10: ='Balance Sheet '!$M$29 -> 0 | G10: ='Balance Sheet '!$M$29 -> 0 | H10: ='Balance Sheet '!$M$29 -> 0 | I10: ='Balance Sheet '!$M$29 -> 0 | J10: =_xlfn.FORMULATEXT(E10) -> ='Balance Sheet '!$M$29
B11: Long-term debt | E11: ='Balance Sheet '!$M$28+'Balance Sheet '!$M$23 -> 1622460.4 | F11: ='Balance Sheet '!$M$28+'Balance Sheet '!$M$23 -> 1622460.4 | G11: ='Balance Sheet '!$M$28+'Balance Sheet '!$M$23 -> 1622460.4 | H11: ='Balance Sheet '!$M$28+'Balance Sheet '!$M$23 -> 1622460.4 | I11: ='Balance Sheet '!$M$28+'Balance Sheet '!$M$23 -> 1622460.4 | J11: =_xlfn.FORMULATEXT(E11) -> ='Balance Sheet '!$M$28+'Balance Sheet '!$M$23
B12: Cash | E12: ='Balance Sheet '!$M$8 -> 2035383.4 | F12: ='Balance Sheet '!$M$8 -> 2035383.4 | G12: ='Balance Sheet '!$M$8 -> 2035383.4 | H12: ='Balance Sheet '!$M$8 -> 2035383.4 | I12: ='Balance Sheet '!$M$8 -> 2035383.4 | J12: =_xlfn.FORMULATEXT(E12) -> ='Balance Sheet '!$M$8
B14: Equity value | D14: %ownership | E14: =E8-(E10+E11-E12) -> 6474405.7 | F14: =F8-(F10+F11-F12) -> 6982650.5 | G14: =G8-(G10+G11-G12) -> 7490895.2 | H14: =H8-(H10+H11-H12) -> 7999140 | I14: =I8-(I10+I11-I12) -> 8507384.8 | J14: =_xlfn.FORMULATEXT(E14) -> =E8-(E10+E11-E12)
B15: Management rollover | D15: =1-'Transaction Summary'!$C$11 -> 0 | E15: =$D$15*E14 -> 0 | F15: =$D$15*F14 -> 0 | G15: =$D$15*G14 -> 0 | H15: =$D$15*H14 -> 0 | I15: =$D$15*I14 -> 0 | J15: =_xlfn.FORMULATEXT(E15) -> =$D$15*E14
B16: Sponser Equity | D16: ='Transaction Summary'!C11 -> 1 | E16: =$D$16*E14 -> 6474405.7 | F16: =$D$16*F14 -> 6982650.5 | G16: =$D$16*G14 -> 7490895.2 | H16: =$D$16*H14 -> 7999140 | I16: =$D$16*I14 -> 8507384.8 | J16: =_xlfn.FORMULATEXT(E16) -> =$D$16*E14
B19: IRR at various exit EV/ LTM EBITDA multiples
D20: IRR | E20: 2025 | F20: 2026 | G20: 2027 | H20: 2028 | I20: 2029
B21: {=TRANSPOSE(E6:I6)} -> 5.9631531 | D21: =IRR(E21:I21) -> 0.22374067 | E21: =-'Transaction Summary'!$C$40 -> -2886970.4 | F21: 0 | G21: 0 | H21: 0 | I21: {=TRANSPOSE((E16:I16))} -> 6474405.7 | J21: =_xlfn.FORMULATEXT(I21) -> =TRANSPOSE((E16:I16))
B22: 6.4631531 | D22: =IRR(E22:I22) -> 0.24708051 | E22: =-'Transaction Summary'!$C$40 -> -2886970.4 | F22: 0 | G22: 0 | H22: 0 | I22: 6982650.5
B23: 6.9631531 | D23: =IRR(E23:I23) -> 0.26917891 | E23: =-'Transaction Summary'!$C$40 -> -2886970.4 | F23: 0 | G23: 0 | H23: 0 | I23: 7490895.2
B24: 7.4631531 | D24: =IRR(E24:I24) -> 0.29017981 | E24: =-'Transaction Summary'!$C$40 -> -2886970.4 | F24: 0 | G24: 0 | H24: 0 | I24: 7999140
B25: 7.9631531 | D25: =IRR(E25:I25) -> 0.31020254 | E25: =-'Transaction Summary'!$C$40 -> -2886970.4 | F25: 0 | G25: 0 | H25: 0 | I25: 8507384.8
D26: =_xlfn.FORMULATEXT(D25) -> =IRR(E25:I25) | E26: =_xlfn.FORMULATEXT(E21) -> =-'Transaction Summary'!$C$40
B29: Pricing at various IRR
B31: IRR | E31: 0.25 | F31: =E31-0.01 -> 0.24 | G31: =F31-0.01 -> 0.23 | H31: =G31-0.01 -> 0.22 | I31: =H31-0.01 -> 0.21 | J31: =I31-0.01 -> 0.2
B32: Sponser Equity | E32: =-PV(E31,4,0,$I$23) -> 3068270.7 | F32: =-PV(F31,4,0,$I$23) -> 3168450.9 | G32: =-PV(G31,4,0,$I$23) -> 3272753.4 | H32: =-PV(H31,4,0,$I$23) -> 3381383.3 | I32: =-PV(I31,4,0,$I$23) -> 3494557.9 | J32: =-PV(J31,4,0,$I$23) -> 3612507.3 | K32: =_xlfn.FORMULATEXT(E32) -> =-PV(E31,4,0,$I$23)
B33: Offer value | E33: =(E32+'Transaction Summary'!$C$37+'Transaction Summary'!$C$38-'Transaction Summary'!$C$39)/'Transaction Summary'!$C$11 -> 7410923.2 | F33: =(F32+'Transaction Summary'!$C$37+'Transaction Summary'!$C$38-'Transaction Summary'!$C$39)/'Transaction Summary'!$C$11 -> 7511103.5 | G33: =(G32+'Transaction Summary'!$C$37+'Transaction Summary'!$C$38-'Transaction Summary'!$C$39)/'Transaction Summary'!$C$11 -> 7615405.9 | H33: =(H32+'Transaction Summary'!$C$37+'Transaction Summary'!$C$38-'Transaction Summary'!$C$39)/'Transaction Summary'!$C$11 -> 7724035.8 | I33: =(I32+'Transaction Summary'!$C$37+'Transaction Summary'!$C$38-'Transaction Summary'!$C$39)/'Transaction Summary'!$C$11 -> 7837210.5 | J33: =(J32+'Transaction Summary'!$C$37+'Transaction Summary'!$C$38-'Transaction Summary'!$C$39)/'Transaction Summary'!$C$11 -> 7955159.9 | K33: =_xlfn.FORMULATEXT(E33) -> =(E32+'Transaction Summary'!$C$37+'Transaction Summary'!$C$38-'Transaction Summary'!$C$39)/'Transaction Summary'!$C$11
B34: Shares outstanding | E34: ='Transaction Summary'!$C$10 -> 59382 | F34: ='Transaction Summary'!$C$10 -> 59382 | G34: ='Transaction Summary'!$C$10 -> 59382 | H34: ='Transaction Summary'!$C$10 -> 59382 | I34: ='Transaction Summary'!$C$10 -> 59382 | J34: ='Transaction Summary'!$C$10 -> 59382 | K34: =_xlfn.FORMULATEXT(E34) -> ='Transaction Summary'!$C$10
B35: Offer value/share at entry | E35: =E33/E34 -> 124.80084 | F35: =F33/F34 -> 126.48788 | G35: =G33/G34 -> 128.24435 | H35: =H33/H34 -> 130.07369 | I35: =I33/I34 -> 131.97956 | J35: =J33/J34 -> 133.96585 | K35: =_xlfn.FORMULATEXT(E35) -> =E33/E34
B37: Enterprise value | E37: =E33+'Transaction Summary'!$H$13 -> 8022638 | F37: =F33+'Transaction Summary'!$H$13 -> 8122818.2 | G37: =G33+'Transaction Summary'!$H$13 -> 8227120.7 | H37: =H33+'Transaction Summary'!$H$13 -> 8335750.6 | I37: =I33+'Transaction Summary'!$H$13 -> 8448925.2 | J37: =J33+'Transaction Summary'!$H$13 -> 8566874.7 | K37: =_xlfn.FORMULATEXT(E37) -> =E33+'Transaction Summary'!$H$13
B38: EV/ LTM EBITDA multiple at entry | E38: =E37/'Transaction Summary'!$C$12 -> 8.3777954 | F38: =F37/'Transaction Summary'!$C$12 -> 8.4824106 | G38: =G37/'Transaction Summary'!$C$12 -> 8.5913304 | H38: =H37/'Transaction Summary'!$C$12 -> 8.7047693 | I38: =I37/'Transaction Summary'!$C$12 -> 8.8229541 | J38: =J37/'Transaction Summary'!$C$12 -> 8.9461251 | K38: =_xlfn.FORMULATEXT(E38) -> =E37/'Transaction Summary'!$C$12

Sheet Balance Sheet 
B2: ='Assumptions '!C5&" Balance Sheet" -> CROCS, INC. Balance Sheet
B3: ='Assumptions '!B3 -> (Dollars in Thousands Except Per Share Data)
B4: Note: Some of the 10-K items were grouped
B6: Assets | D6: =E6-1 -> 2023 | E6: =I6-1 -> 2024 | F6: 2025 | G6: Adjustment (-) | H6: Adjustment (+) | I6: ='Assumptions '!D12 -> 2025 | J6: ='Assumptions '!E12 -> 2026 | K6: ='Assumptions '!F12 -> 2027 | L6: ='Assumptions '!G12 -> 2028 | M6: ='Assumptions '!H12 -> 2029
B8: Cash and Cash Equivalents | D8: 149288 | E8: 180485 | F8: 512223.38 | G8: =-F8 -> -512223.38 | I8: =SUM(F8:H8) -> 0 | J8: ='Statement of Cash Flow'!E37 -> 521650.66 | K8: ='Statement of Cash Flow'!F37 -> 996749.42 | L8: ='Statement of Cash Flow'!G37 -> 1516665 | M8: ='Statement of Cash Flow'!H37 -> 2035383.4 | N8: =_xlfn.FORMULATEXT(G8) -> =-F8
B9: Accounts Receivable | D9: =305747+21071 -> 326818 | E9: =257657+22204 -> 279861 | F9: 313730.09 | I9: =SUM(F9:H9) -> 313730.09 | J9: ='WC Schedule'!G12 -> 303371.35 | K9: ='WC Schedule'!H12 -> 315571.63 | L9: ='WC Schedule'!I12 -> 316438.88 | M9: ='WC Schedule'!J12 -> 323175.7
B10: Inventories | D10: 385054 | E10: 356254 | F10: 403108.21 | I10: =SUM(F10:H10) -> 403108.21 | J10: ='WC Schedule'!G13 -> 404793.99 | K10: ='WC Schedule'!H13 -> 413084.79 | L10: ='WC Schedule'!I13 -> 418176.02 | M10: ='WC Schedule'!J13 -> 425046.35
B11: Prepaid Expenses | D11: 45129 | E11: 51623 | F11: 49907.926 | I11: =SUM(F11:H11) -> 49907.926 | J11: ='WC Schedule'!G14 -> 51918.74 | K11: ='WC Schedule'!H14 -> 52057.686 | L11: ='WC Schedule'!I14 -> 53165.948 | M11: ='WC Schedule'!J14 -> 53801.947
B12: Other Current Assets | D12: =31446+4413 -> 35859 | E12: =24207+4046 -> 28253 | F12: 33177.707 | I12: =SUM(F12:H12) -> 33177.707 | J12: ='WC Schedule'!G15 -> 31390.491 | K12: ='WC Schedule'!H15 -> 33021.383 | L12: ='WC Schedule'!I15 -> 32929.64 | M12: ='WC Schedule'!J15 -> 33724.451
B13: Property and Equipment, Net | D13: 238315 | E13: 244335 | F13: 282885.72 | I13: =SUM(F13:H13) -> 282885.72 | J13: ='PPE Schedule'!I10 -> 302407.68 | K13: ='PPE Schedule'!J10 -> 321583.85 | L13: ='PPE Schedule'!K10 -> 330785.44 | M13: ='PPE Schedule'!L10 -> 334749.69
B14: Intangible assets, net | D14: =1792562+287440 -> 2080002 | E14: =1777080+307228 -> 2084308 | F14: 2081755 | I14: =SUM(F14:H14) -> 2081755 | J14: ='Assumptions '!E44*'Income Statement '!G9 -> 2112966.8 | K14: ='Assumptions '!F44*'Income Statement '!H9 -> 2144698.6 | L14: ='Assumptions '!G44*'Income Statement '!I9 -> 2176959.8 | M14: ='Assumptions '!H44*'Income Statement '!J9 -> 2209759.9
B15: Other Non-Current Assets | D15: =711588+667972+3807+2 -> 1383369 | E15: =711491+872350+3193 -> 1587034 | F15: 1665404 | I15: =SUM(F15:H15) -> 1665404 | J15: ='Assumptions '!E45*'Income Statement '!G9 -> 1690373.4 | K15: ='Assumptions '!F45*'Income Statement '!H9 -> 1715758.9 | L15: ='Assumptions '!G45*'Income Statement '!I9 -> 1741567.8 | M15: ='Assumptions '!H45*'Income Statement '!J9 -> 1767807.9
B17: Total Assets | D17: =SUM(D8:D15) -> 4643834 | E17: =SUM(E8:E15) -> 4812153 | F17: 5342192 | I17: =SUM(I8:I15) -> 4829968.6 | J17: =SUM(J8:J15) -> 5418873.1 | K17: =SUM(K8:K15) -> 5992526.3 | L17: =SUM(L8:L15) -> 6586688.5 | M17: =SUM(M8:M15) -> 7183449.2
B19: Liabilities & Stockholder's Equity
B20: Current Liabilities
B21: Accounts Payable | D21: 260978 | E21: 264901 | F21: 286195.03 | I21: =SUM(F21:H21) -> 286195.03 | J21: ='WC Schedule'!G18 -> 294119.75 | K21: ='WC Schedule'!H18 -> 296692.56 | L21: ='WC Schedule'!I18 -> 302091.45 | M21: ='WC Schedule'!J18 -> 306168.01
B22: Accrued Expenses and Other Current Liabilities | D22: =285771+65952+62267 -> 413990 | E22: =298068+108688+68551 -> 475307 | F22: 458714.65 | I22: =SUM(F22:H22) -> 458714.65 | J22: ='WC Schedule'!G19 -> 477623.36 | K22: ='WC Schedule'!H19 -> 478690.21 | L22: ='WC Schedule'!I19 -> 488989.69 | M22: ='WC Schedule'!J19 -> 494784.47
B23: Current portion of debt | D23: 23328 | E23: 0 | F23: 23000 | G23: =-F23 -> -23000 | H23: ='Transaction Summary'!C56 -> 547204.17 | I23: =SUM(F23:H23) -> 547204.17 | J23: =MIN('Transaction Summary'!$C$55,I28) -> 547204.17 | K23: =MIN('Transaction Summary'!$C$55,J28) -> 547204.17 | L23: =MIN('Transaction Summary'!$C$55,K28) -> 547204.17 | M23: =MIN('Transaction Summary'!$C$55,L28) -> 547204.17 | N23: =_xlfn.FORMULATEXT(G23) -> =-F23 | O23: =_xlfn.FORMULATEXT(H23) -> ='Transaction Summary'!C56
B24: Total Current Liabilities | D24: =SUM(D21:D23) -> 698296 | E24: =SUM(E21:E23) -> 740208 | F24: 767909.68 | I24: =SUM(I21:I23) -> 1292113.8 | J24: =SUM(J21:J23) -> 1318947.3 | K24: =SUM(K21:K23) -> 1322586.9 | L24: =SUM(L21:L23) -> 1338285.3 | M24: =SUM(M21:M23) -> 1348156.6
B26: Non-Current Liabilities
B27: Long Term Income Tax | D27: 565171 | E27: 595434 | F27: 582891.4 | I27: =SUM(F27:H27) -> 582891.4 | J27: ='Assumptions '!E57*'Income Statement '!G9 -> 591630.7 | K27: ='Assumptions '!F57*'Income Statement '!H9 -> 600515.61 | L27: ='Assumptions '!G57*'Income Statement '!I9 -> 609548.74 | M27: ='Assumptions '!H57*'Income Statement '!J9 -> 618732.76
B28: Long Term Debt | D28: 1640996 | E28: 1349339 | F28: 1100938.1 | G28: =-F28 -> -1100938.1 | H28: ='Transaction Summary'!C57-'Transaction Summary'!C30 -> 3264072.9 | I28: =SUM(F28:H28) -> 3264072.9 | J28: ='Debt & Equity Schedule'!F33-'Balance Sheet '!J23 -> 2716868.7 | K28: ='Debt & Equity Schedule'!G33-'Balance Sheet '!K23 -> 2169664.5 | L28: ='Debt & Equity Schedule'!H33-'Balance Sheet '!L23 -> 1622460.4 | M28: ='Debt & Equity Schedule'!I33-'Balance Sheet '!M23 -> 1075256.2 | N28: =_xlfn.FORMULATEXT(G28) -> =-F28 | O28: =_xlfn.FORMULATEXT(H28) -> ='Transaction Summary'!C57-'Transaction Summary'!C30
B29: Revolving Line of Credit | D29: 0 | E29: 0 | F29: 0 | G29: =-F29 -> 0 | I29: ='Debt & Equity Schedule'!E23 -> 0 | J29: ='Debt & Equity Schedule'!F23 -> 0 | K29: ='Debt & Equity Schedule'!G23 -> 0 | L29: ='Debt & Equity Schedule'!H23 -> 0 | M29: ='Debt & Equity Schedule'!I23 -> 0 | N29: =_xlfn.FORMULATEXT(G29) -> =-F29
B30: Deferred Tax Liabilities | D30: 12912 | E30: 4086 | F30: 16654.04 | I30: =SUM(F30:H30) -> 16654.04 | J30: ='Assumptions '!E58*'Income Statement '!G9 -> 16903.734 | K30: ='Assumptions '!F58*'Income Statement '!H9 -> 17157.589 | L30: ='Assumptions '!G58*'Income Statement '!I9 -> 17415.678 | M30: ='Assumptions '!H58*'Income Statement '!J9 -> 17678.079
B31: Other Long-Term Liabilities | D31: =2767+269769 -> 272536 | E31: =3948+283406 -> 287354 | F31: 249810.6 | I31: =SUM(F31:H31) -> 249810.6 | J31: ='Assumptions '!E59*'Income Statement '!G9 -> 253556.02 | K31: ='Assumptions '!F59*'Income Statement '!H9 -> 257363.83 | L31: ='Assumptions '!G59*'Income Statement '!I9 -> 261235.17 | M31: ='Assumptions '!H59*'Income Statement '!J9 -> 265171.18
B32: Total Non-Current Liabilities | D32: =SUM(D27:D31) -> 2491615 | E32: =SUM(E27:E31) -> 2236213 | F32: 1950294.2 | I32: =SUM(I27:I31) -> 4113428.9 | J32: =SUM(J27:J31) -> 3578959.2 | K32: =SUM(K27:K31) -> 3044701.6 | L32: =SUM(L27:L31) -> 2510660 | M32: =SUM(M27:M31) -> 1976838.2
B34: Total Liabilities | D34: =D24+D32 -> 3189911 | E34: =E24+E32 -> 2976421 | F34: 2718203.9 | I34: =I24+I32 -> 5405542.8 | J34: =J24+J32 -> 4897906.4 | K34: =K24+K32 -> 4367288.5 | L34: =L24+L32 -> 3848945.3 | M34: =M24+M32 -> 3324994.9
B37: Total stockholders' equity | D37: 1453923 | E37: 1835732 | F37: 2623988.1 | G37: =-'Transaction Summary'!C31-'Transaction Summary'!C29 -> -6086532.7 | H37: ='Transaction Summary'!C40+'Transaction Summary'!C39 -> 2886970.4 | I37: =SUM(F37:H37) -> -575574.12 | J37: ='Debt & Equity Schedule'!F76 -> 520966.73 | K37: ='Debt & Equity Schedule'!G76 -> 1625237.8 | L37: ='Debt & Equity Schedule'!H76 -> 2737743.2 | M37: ='Debt & Equity Schedule'!I76 -> 3858454.4 | N37: =_xlfn.FORMULATEXT(G37) -> =-'Transaction Summary'!C31-'Transaction Summary'!C29 | O37: =_xlfn.FORMULATEXT(H37) -> ='Transaction Summary'!C40+'Transaction Summary'!C39
B39: Total liabilities and stockholders' equity | D39: =D34+D37 -> 4643834 | E39: =E34+E37 -> 4812153 | F39: 5342192 | I39: =I34+I37 -> 4829968.6 | J39: =J34+J37 -> 5418873.1 | K39: =K34+K37 -> 5992526.3 | L39: =L34+L37 -> 6586688.5 | M39: =M34+M37 -> 7183449.2
B42: Balance check | D42: =ROUND(D17-D39, 3) -> 0 | E42: =ROUND(E17-E39, 3) -> 0 | F42: 0 | I42: =ROUND(I17-I39, 3) -> 0 | J42: =ROUND(J17-J39, 3) -> 0 | K42: =ROUND(K17-K39, 3) -> 0 | L42: =ROUND(L17-L39, 3) -> 0 | M42: =ROUND(M17-M39, 3) -> 0

Sheet Debt & Equity Schedule
B2: ='Assumptions '!C5& " Debt and Equity Schedule" -> CROCS, INC. Debt and Equity Schedule
E4: ='Assumptions '!D12 -> 2025 | F4: ='Assumptions '!E12 -> 2026 | G4: ='Assumptions '!F12 -> 2027 | H4: ='Assumptions '!G12 -> 2028 | I4: ='Assumptions '!H12 -> 2029
B6: Beginning Cash Balance | E6: ='Balance Sheet '!E8 -> 180485 | F6: ='Balance Sheet '!I8 -> 0 | G6: ='Balance Sheet '!J8 -> 521650.66 | H6: ='Balance Sheet '!K8 -> 996749.42 | I6: ='Balance Sheet '!L8 -> 1516665 | J6: =_xlfn.FORMULATEXT(E6) -> ='Balance Sheet '!E8
B7: CFO + CFI | E7: ='Statement of Cash Flow'!D18+'Statement of Cash Flow'!D24 -> 907225.23 | F7: ='Statement of Cash Flow'!E18+'Statement of Cash Flow'!E24 -> 1056370.1 | G7: ='Statement of Cash Flow'!F18+'Statement of Cash Flow'!F24 -> 1009610.2 | H7: ='Statement of Cash Flow'!G18+'Statement of Cash Flow'!G24 -> 1054215.3 | I7: ='Statement of Cash Flow'!H18+'Statement of Cash Flow'!H24 -> 1052802.5 | J7: =_xlfn.FORMULATEXT(E7) -> ='Statement of Cash Flow'!D18+'Statement of Cash Flow'!D24
B8: (Minimum required cash balance) | E8: =-'Assumptions '!D64*'Income Statement '!F9 -> -62452.65 | F8: =-'Assumptions '!E64*'Income Statement '!G9 -> -63389.004 | G8: =-'Assumptions '!F64*'Income Statement '!H9 -> -64340.958 | H8: =-'Assumptions '!G64*'Income Statement '!I9 -> -65308.794 | I8: =-'Assumptions '!H64*'Income Statement '!J9 -> -66292.796 | J8: =_xlfn.FORMULATEXT(E8) -> =-'Assumptions '!D64*'Income Statement '!F9
B9: =B74 -> Stock Issuance (Repurchases) | E9: =-E74 -> 0 | F9: =-F74 -> 0 | G9: =-G74 -> 0 | H9: =-H74 -> 0 | I9: =-I74 -> 0 | J9: =_xlfn.FORMULATEXT(E9) -> =-E74
B10: =B75 -> (Dividends Payout) | E10: =E75 -> 0 | F10: =F75 -> 0 | G10: =G75 -> 0 | H10: =H75 -> 0 | I10: =I75 -> 0 | J10: =_xlfn.FORMULATEXT(E10) -> =E75
B11: ='Statement of Cash Flow'!B30 -> Increase (Decrease) in Other Long-Term Liabilities | E11: ='Balance Sheet '!I31-'Balance Sheet '!E31 -> -37543.401 | F11: ='Balance Sheet '!J31-'Balance Sheet '!I31 -> 3745.4171 | G11: ='Balance Sheet '!K31-'Balance Sheet '!J31 -> 3807.8175 | H11: ='Balance Sheet '!L31-'Balance Sheet '!K31 -> 3871.3408 | I11: ='Balance Sheet '!M31-'Balance Sheet '!L31 -> 3936.0082 | J11: =_xlfn.FORMULATEXT(E11) -> ='Balance Sheet '!I31-'Balance Sheet '!E31
B12: Cash available for Debt | E12: =SUM(E6:E11) -> 987714.18 | F12: =SUM(F6:F11) -> 996726.52 | G12: =SUM(G6:G11) -> 1470727.7 | H12: =SUM(H6:H11) -> 1989527.2 | I12: =SUM(I6:I11) -> 2507110.7 | J12: =_xlfn.FORMULATEXT(E12) -> =SUM(E6:E11)
B13: Mandatory long term debt repayment | E13: =-'Balance Sheet '!I23 -> -547204.17 | F13: =-'Balance Sheet '!J23 -> -547204.17 | G13: =-'Balance Sheet '!K23 -> -547204.17 | H13: =-'Balance Sheet '!L23 -> -547204.17 | I13: =-'Balance Sheet '!M23 -> -547204.17 | J13: =_xlfn.FORMULATEXT(E13) -> =-'Balance Sheet '!I23
B14: Other long term debt issuance/(repayment) | E14: 0 | F14: 0 | G14: 0 | H14: 0 | I14: 0
B15: Cash available for revolver and accelerated long term debt repayment | E15: =SUM(E12:E14) -> 440510.01 | F15: =SUM(F12:F14) -> 449522.35 | G15: =SUM(G12:G14) -> 923523.55 | H15: =SUM(H12:H14) -> 1442323.1 | I15: =SUM(I12:I14) -> 1959906.6 | J15: =_xlfn.FORMULATEXT(E15) -> =SUM(E12:E14)
B16: Accelerated long term debt repayment | E16: =-MIN(E15-E20,E31+E13) -> -440510.01 | F16: =-MIN(F15-F20,F31+F13) -> -449522.35 | G16: =-MIN(G15-G20,G31+G13) -> -923523.55 | H16: =-MIN(H15-H20,H31+H13) -> -1442323.1 | I16: =-MIN(I15-I20,I31+I13) -> -1622460.4 | J16: =_xlfn.FORMULATEXT(E16) -> =-MIN(E15-E20,E31+E13)
B17: Cash available for Revolving Line of Credit | E17: =SUM(E15:E16) -> 0 | F17: =SUM(F15:F16) -> 0 | G17: =SUM(G15:G16) -> 0 | H17: =SUM(H15:H16) -> 0 | I17: =SUM(I15:I16) -> 337446.2 | J17: =_xlfn.FORMULATEXT(E17) -> =SUM(E15:E16)
B19: Revolving Line of Credit
B20: Beginning balance | E20: =D23 -> 0 | F20: =E23 -> 0 | G20: =F23 -> 0 | H20: =G23 -> 0 | I20: =H23 -> 0 | J20: =_xlfn.FORMULATEXT(E20) -> =D23
B21: Issuance/(repayment) on Revolving Line of Credit | E21: =-MIN(E17,E20) -> 0 | F21: =-MIN(F17,F20) -> 0 | G21: =-MIN(G17,G20) -> 0 | H21: =-MIN(H17,H20) -> 0 | I21: =-MIN(I17,I20) -> 0 | J21: =_xlfn.FORMULATEXT(E21) -> =-MIN(E17,E20)
B22: Ending balance limit | E22: =0.6*AVERAGE('Balance Sheet '!I9:J9)+0.8*AVERAGE('Balance Sheet '!I10:J10) -> 508291.31 | F22: =0.6*AVERAGE('Balance Sheet '!J9:K9)+0.8*AVERAGE('Balance Sheet '!J10:K10) -> 512834.4 | G22: =0.6*AVERAGE('Balance Sheet '!K9:L9)+0.8*AVERAGE('Balance Sheet '!K10:L10) -> 522107.48 | H22: =0.6*AVERAGE('Balance Sheet '!L9:M9)+0.8*AVERAGE('Balance Sheet '!L10:M10) -> 529173.32 | I22: =0.6*AVERAGE('Balance Sheet '!M9:N9)+0.8*AVERAGE('Balance Sheet '!M10:N10) -> 533942.5 | J22: =_xlfn.FORMULATEXT(E22) -> =0.6*AVERAGE('Balance Sheet '!I9:J9)+0.8*AVERAGE('Balance Sheet '!I10:J10)
B23: Ending balance | D23: ='Balance Sheet '!I29 -> 0 | E23: =MIN((E20+E21),E22) -> 0 | F23: =MIN((F20+F21),F22) -> 0 | G23: =MIN((G20+G21),G22) -> 0 | H23: =MIN((H20+H21),H22) -> 0 | I23: =MIN((I20+I21),I22) -> 0 | J23: =_xlfn.FORMULATEXT(E23) -> =MIN((E20+E21),E22)
B25: Short term borrowings (total)
B26: Beginning balance | E26: =D28 -> 0 | F26: =E28 -> 0 | G26: =F28 -> 0 | H26: =G28 -> 0 | I26: =H28 -> 0 | J26: =_xlfn.FORMULATEXT(E26) -> =D28
B27: Total long term debt issuance/(repayment) | E27: =IF(SUM(E20:E21)>E22,SUM(E20:E21)-E22,0) -> 0 | F27: =IF(SUM(F20:F21)>F22,SUM(F20:F21)-F22,0) -> 0 | G27: =IF(SUM(G20:G21)>G22,SUM(G20:G21)-G22,0) -> 0 | H27: =IF(SUM(H20:H21)>H22,SUM(H20:H21)-H22,0) -> 0 | I27: =IF(SUM(I20:I21)>I22,SUM(I20:I21)-I22,0) -> 0 | J27: =_xlfn.FORMULATEXT(E27) -> =IF(SUM(E20:E21)>E22,SUM(E20:E21)-E22,0)
B28: Ending balance | D28: 0 | E28: =SUM(E26:E27) -> 0 | F28: =SUM(F26:F27) -> 0 | G28: =SUM(G26:G27) -> 0 | H28: =SUM(H26:H27) -> 0 | I28: =SUM(I26:I27) -> 0 | J28: =_xlfn.FORMULATEXT(E28) -> =SUM(E26:E27)
B30: ='Balance Sheet '!B28 &" Total" -> Long Term Debt Total
B31: Beginning balance | E31: =D33 -> 1349339 | F31: =E33 -> 3811277 | G31: =F33 -> 3264072.9 | H31: =G33 -> 2716868.7 | I31: =H33 -> 2169664.5 | J31: =_xlfn.FORMULATEXT(E31) -> =D33
B32: ="Issuance/(repayment) on "&'Balance Sheet '!B28 &" Total" -> Issuance/(repayment) on Long Term Debt Total | E32: =E13+E14 -> -547204.17 | F32: =F13+F14 -> -547204.17 | G32: =G13+G14 -> -547204.17 | H32: =H13+H14 -> -547204.17 | I32: =I13+I14 -> -547204.17 | J32: =_xlfn.FORMULATEXT(E32) -> =E13+E14
B33: Ending balance | D33: ='Balance Sheet '!E23+'Balance Sheet '!E28 -> 1349339 | E33: ='Balance Sheet '!I28+'Balance Sheet '!I23 -> 3811277 | F33: =SUM(F31:F32) -> 3264072.9 | G33: =SUM(G31:G32) -> 2716868.7 | H33: =SUM(H31:H32) -> 2169664.5 | I33: =SUM(I31:I32) -> 1622460.4 | J33: =_xlfn.FORMULATEXT(F33) -> =SUM(F31:F32)
E34: =_xlfn.FORMULATEXT(E33) -> ='Balance Sheet '!I28+'Balance Sheet '!I23
B35: Interest Expense Calculation
E36: =E4 -> 2025 | F36: =F4 -> 2026 | G36: =G4 -> 2027 | H36: =H4 -> 2028 | I36: =I4 -> 2029
B37: ='Balance Sheet '!B29 -> Revolving Line of Credit
B38: Average balance | E38: =AVERAGE(D23:E23) -> 0 | F38: =AVERAGE(E23:F23) -> 0 | G38: =AVERAGE(F23:G23) -> 0 | H38: =AVERAGE(G23:H23) -> 0 | I38: =AVERAGE(H23:I23) -> 0 | J38: =_xlfn.FORMULATEXT(E38) -> =AVERAGE(D23:E23)
B39: 3-month SOFR (2025/10/01) | E39: 0.043 | F39: 0.043 | G39: 0.043 | H39: 0.043 | I39: 0.043
B40: Interest rate (3-month SOFR+6%) | E40: =E39+6% -> 0.103 | F40: =F39+6% -> 0.103 | G40: =G39+6% -> 0.103 | H40: =H39+6% -> 0.103 | I40: =I39+6% -> 0.103 | J40: =_xlfn.FORMULATEXT(E40) -> =E39+6%
B41: Interest expense | E41: =E38*E40 -> 0 | F41: =F38*F40 -> 0 | G41: =G38*G40 -> 0 | H41: =H38*H40 -> 0 | I41: =I38*I40 -> 0 | J41: =_xlfn.FORMULATEXT(E41) -> =E38*E40
B43: Short term borrowings
B44: Average balance | E44: =AVERAGE(D28:E28) -> 0 | F44: =AVERAGE(E28:F28) -> 0 | G44: =AVERAGE(F28:G28) -> 0 | H44: =AVERAGE(G28:H28) -> 0 | I44: =AVERAGE(H28:I28) -> 0 | J44: =_xlfn.FORMULATEXT(E44) -> =AVERAGE(D28:E28)
B45: 3-month SOFR (2025/10/01) | E45: 0.0434738 | F45: 0.0434738 | G45: 0.0434738 | H45: 0.0434738 | I45: 0.0434738
B46: Interest rate 1 (3-month SOFR+7%) | E46: =E45+7% -> 0.1134738 | F46: =F45+7% -> 0.1134738 | G46: =G45+7% -> 0.1134738 | H46: =H45+7% -> 0.1134738 | I46: =I45+7% -> 0.1134738 | J46: =_xlfn.FORMULATEXT(E46) -> =E45+7%
B47: Interest rate 2 (3-month SOFR+12%) | E47: =E45+12% -> 0.1634738 | F47: =F45+12% -> 0.1634738 | G47: =G45+12% -> 0.1634738 | H47: =H45+12% -> 0.1634738 | I47: =I45+12% -> 0.1634738 | J47: =_xlfn.FORMULATEXT(E47) -> =E45+12%
...

Sheet Statement of Cash Flow
B2: ='Assumptions '!C5& "Cash Flow Statement" -> CROCS, INC.Cash Flow Statement
D6: ='Assumptions '!D12 -> 2025 | E6: ='Assumptions '!E12 -> 2026 | F6: ='Assumptions '!F12 -> 2027 | G6: ='Assumptions '!G12 -> 2028 | H6: ='Assumptions '!H12 -> 2029
B8: Cash Flow from Operations
B9: ='Income Statement '!B25 -> Net income | D9: ='Income Statement '!F25 -> 1088256.1 | E9: ='Income Statement '!G25 -> 1096540.8 | F9: ='Income Statement '!H25 -> 1104271 | G9: ='Income Statement '!I25 -> 1112505.5 | H9: ='Income Statement '!J25 -> 1120711.1
B10: ='Income Statement '!B15 -> Depreciation and Amortization | D10: =-'Income Statement '!F15 -> 57389.352 | E10: =-'Income Statement '!G15 -> 64887.435 | F10: =-'Income Statement '!H15 -> 73082.794 | G10: =-'Income Statement '!I15 -> 81104.697 | H10: =-'Income Statement '!J15 -> 89398.067
B11: ="(Increase) Decrease in "&'Balance Sheet '!B9 -> (Increase) Decrease in Accounts Receivable | D11: ='Balance Sheet '!E9-'Balance Sheet '!I9 -> -33869.088 | E11: ='Balance Sheet '!I9-'Balance Sheet '!J9 -> 10358.742 | F11: ='Balance Sheet '!J9-'Balance Sheet '!K9 -> -12200.282 | G11: ='Balance Sheet '!K9-'Balance Sheet '!L9 -> -867.24758 | H11: ='Balance Sheet '!L9-'Balance Sheet '!M9 -> -6736.8209
B12: ="(Increase) Decrease in "&'Balance Sheet '!B10 -> (Increase) Decrease in Inventories | D12: ='Balance Sheet '!E10-'Balance Sheet '!I10 -> -46854.207 | E12: ='Balance Sheet '!I10-'Balance Sheet '!J10 -> -1685.7851 | F12: ='Balance Sheet '!J10-'Balance Sheet '!K10 -> -8290.7949 | G12: ='Balance Sheet '!K10-'Balance Sheet '!L10 -> -5091.2367 | H12: ='Balance Sheet '!L10-'Balance Sheet '!M10 -> -6870.3308
B13: ="(Increase) Decrease in "&'Balance Sheet '!B11 -> (Increase) Decrease in Prepaid Expenses | D13: ='Balance Sheet '!E11-'Balance Sheet '!I11 -> 1715.0742 | E13: ='Balance Sheet '!I11-'Balance Sheet '!J11 -> -2010.8145 | F13: ='Balance Sheet '!J11-'Balance Sheet '!K11 -> -138.94585 | G13: ='Balance Sheet '!K11-'Balance Sheet '!L11 -> -1108.2619 | H13: ='Balance Sheet '!L11-'Balance Sheet '!M11 -> -635.99939
B14: ="(Increase) Decrease in "&'Balance Sheet '!B12 -> (Increase) Decrease in Other Current Assets | D14: ='Balance Sheet '!E12-'Balance Sheet '!I12 -> -4924.7074 | E14: ='Balance Sheet '!I12-'Balance Sheet '!J12 -> 1787.2162 | F14: ='Balance Sheet '!J12-'Balance Sheet '!K12 -> -1630.892 | G14: ='Balance Sheet '!K12-'Balance Sheet '!L12 -> 91.74363 | H14: ='Balance Sheet '!L12-'Balance Sheet '!M12 -> -794.81162
B15: ="(Increase) Decrease in "&'Balance Sheet '!B21 -> (Increase) Decrease in Accounts Payable | D15: ='Balance Sheet '!I21-'Balance Sheet '!E21 -> 21294.032 | E15: ='Balance Sheet '!J21-'Balance Sheet '!I21 -> 7924.7158 | F15: ='Balance Sheet '!K21-'Balance Sheet '!J21 -> 2572.8113 | G15: ='Balance Sheet '!L21-'Balance Sheet '!K21 -> 5398.8943 | H15: ='Balance Sheet '!M21-'Balance Sheet '!L21 -> 4076.5556
B16: ="(Increase) Decrease in "&'Balance Sheet '!B22 -> (Increase) Decrease in Accrued Expenses and Other Current Liabilities | D16: ='Balance Sheet '!I22-'Balance Sheet '!E22 -> -16592.353 | E16: ='Balance Sheet '!J22-'Balance Sheet '!I22 -> 18908.709 | F16: ='Balance Sheet '!K22-'Balance Sheet '!J22 -> 1066.8501 | G16: ='Balance Sheet '!L22-'Balance Sheet '!K22 -> 10299.486 | H16: ='Balance Sheet '!M22-'Balance Sheet '!L22 -> 5794.7756
B17: ="(Increase) Decrease in "&'Balance Sheet '!B30 -> (Increase) Decrease in Deferred Tax Liabilities | D17: ='Balance Sheet '!I30-'Balance Sheet '!E30 -> 12568.04 | E17: ='Balance Sheet '!J30-'Balance Sheet '!I30 -> 249.69447 | F17: ='Balance Sheet '!K30-'Balance Sheet '!J30 -> 253.8545 | G17: ='Balance Sheet '!L30-'Balance Sheet '!K30 -> 258.08939 | H17: ='Balance Sheet '!M30-'Balance Sheet '!L30 -> 262.40055
B18: Total | D18: =SUM(D9:D17) -> 1078982.3 | E18: =SUM(E9:E17) -> 1196960.8 | F18: =SUM(F9:F17) -> 1158986.4 | G18: =SUM(G9:G17) -> 1202591.6 | H18: =SUM(H9:H17) -> 1205205
B20: Cash Flow from Investing
B21: ="(Purchase) in "&'Balance Sheet '!B13 -> (Purchase) in Property and Equipment, Net | D21: =-'PPE Schedule'!H8 -> -95940.069 | E21: =-'PPE Schedule'!I8 -> -84409.399 | F21: =-'PPE Schedule'!J8 -> -92258.964 | G21: =-'PPE Schedule'!K8 -> -90306.28 | H21: =-'PPE Schedule'!L8 -> -93362.317
B22: ="(Purchase) in "&'Balance Sheet '!B14 -> (Purchase) in Intangible assets, net | D22: ='Balance Sheet '!E14-'Balance Sheet '!I14 -> 2553.01 | E22: ='Balance Sheet '!I14-'Balance Sheet '!J14 -> -31211.809 | F22: ='Balance Sheet '!J14-'Balance Sheet '!K14 -> -31731.812 | G22: ='Balance Sheet '!K14-'Balance Sheet '!L14 -> -32261.173 | H22: ='Balance Sheet '!L14-'Balance Sheet '!M14 -> -32800.069
B23: ="(Purchase) in "&'Balance Sheet '!B15 -> (Purchase) in Other Non-Current Assets | D23: ='Balance Sheet '!E15-'Balance Sheet '!I15 -> -78369.992 | E23: ='Balance Sheet '!I15-'Balance Sheet '!J15 -> -24969.447 | F23: ='Balance Sheet '!J15-'Balance Sheet '!K15 -> -25385.45 | G23: ='Balance Sheet '!K15-'Balance Sheet '!L15 -> -25808.939 | H23: ='Balance Sheet '!L15-'Balance Sheet '!M15 -> -26240.055
B24: Total | D24: =SUM(D21:D23) -> -171757.05 | E24: =SUM(E21:E23) -> -140590.66 | F24: =SUM(F21:F23) -> -149376.23 | G24: =SUM(G21:G23) -> -148376.39 | H24: =SUM(H21:H23) -> -152402.44
B26: Cash Flow from Financing
B27: ="Increase (Decrease) in "&'Balance Sheet '!B28 -> Increase (Decrease) in Long Term Debt | D27: ='Debt & Equity Schedule'!E32 -> -547204.17 | E27: ='Debt & Equity Schedule'!F32 -> -547204.17 | F27: ='Debt & Equity Schedule'!G32 -> -547204.17 | G27: ='Debt & Equity Schedule'!H32 -> -547204.17 | H27: ='Debt & Equity Schedule'!I32 -> -547204.17
B28: ="Increase (Decrease) in "&'Balance Sheet '!B29 -> Increase (Decrease) in Revolving Line of Credit | D28: ='Debt & Equity Schedule'!E21 -> 0 | E28: ='Debt & Equity Schedule'!F21 -> 0 | F28: ='Debt & Equity Schedule'!G21 -> 0 | G28: ='Debt & Equity Schedule'!H21 -> 0 | H28: ='Debt & Equity Schedule'!I21 -> 0
B29: ="Increase (Decrease) in "&'Balance Sheet '!B27 -> Increase (Decrease) in Long Term Income Tax | D29: ='Balance Sheet '!I27-'Balance Sheet '!E27 -> -12542.603 | E29: ='Balance Sheet '!J27-'Balance Sheet '!I27 -> 8739.3065 | F29: ='Balance Sheet '!K27-'Balance Sheet '!J27 -> 8884.9074 | G29: ='Balance Sheet '!L27-'Balance Sheet '!K27 -> 9033.1285 | H29: ='Balance Sheet '!M27-'Balance Sheet '!L27 -> 9184.0192
B30: ="Increase (Decrease) in "&'Balance Sheet '!B31 -> Increase (Decrease) in Other Long-Term Liabilities | D30: ='Balance Sheet '!I31-'Balance Sheet '!E31 -> -37543.401 | E30: ='Balance Sheet '!J31-'Balance Sheet '!I31 -> 3745.4171 | F30: ='Balance Sheet '!K31-'Balance Sheet '!J31 -> 3807.8175 | G30: ='Balance Sheet '!L31-'Balance Sheet '!K31 -> 3871.3408 | H30: ='Balance Sheet '!M31-'Balance Sheet '!L31 -> 3936.0082
B31: ='Debt & Equity Schedule'!B74 -> Stock Issuance (Repurchases) | D31: ='Debt & Equity Schedule'!E9 -> 0 | E31: ='Debt & Equity Schedule'!F9 -> 0 | F31: ='Debt & Equity Schedule'!G9 -> 0 | G31: ='Debt & Equity Schedule'!H9 -> 0 | H31: ='Debt & Equity Schedule'!I9 -> 0
B32: ='Debt & Equity Schedule'!B75 -> (Dividends Payout) | D32: ='Debt & Equity Schedule'!E10 -> 0 | E32: ='Debt & Equity Schedule'!F10 -> 0 | F32: ='Debt & Equity Schedule'!G10 -> 0 | G32: ='Debt & Equity Schedule'!H10 -> 0 | H32: ='Debt & Equity Schedule'!I10 -> 0
B33: Total | D33: =SUM(D27:D32) -> -597290.17 | E33: =SUM(E27:E32) -> -534719.45 | F33: =SUM(F27:F32) -> -534511.44 | G33: =SUM(G27:G32) -> -534299.7 | H33: =SUM(H27:H32) -> -534084.14
B35: Cash at Beginning of Year | D35: =C37 -> 180485 | E35: =D37 -> 0 | F35: =E37 -> 521650.66 | G35: =F37 -> 996749.42 | H35: =G37 -> 1516665
B36: Net Changes in Cash | D36: =D18+D24+D33 -> 309935.06 | E36: =E18+E24+E33 -> 521650.66 | F36: =F18+F24+F33 -> 475098.76 | G36: =G18+G24+G33 -> 519915.56 | H36: =H18+H24+H33 -> 518718.4
B37: Cash at End of Year | C37: ='Balance Sheet '!E8 -> 180485 | D37: ='Balance Sheet '!I8 -> 0 | E37: =SUM(E35:E36) -> 521650.66 | F37: =SUM(F35:F36) -> 996749.42 | G37: =SUM(G35:G36) -> 1516665 | H37: =SUM(H35:H36) -> 2035383.4

Sheet WC Schedule
B2: ='Assumptions '!C5 &" Working Capital Schedule" -> CROCS, INC. Working Capital Schedule
B3: ='Assumptions '!B3 -> (Dollars in Thousands Except Per Share Data)
D6: =E6-1 -> 2023 | E6: =F6-1 -> 2024 | F6: ='Assumptions '!D12 -> 2025 | G6: ='Assumptions '!E12 -> 2026 | H6: ='Assumptions '!F12 -> 2027 | I6: ='Assumptions '!G12 -> 2028 | J6: ='Assumptions '!H12 -> 2029
B7: INCOME STATEMENT ACCOUNTS
B8: Total Revenue | D8: ='Income Statement '!D9 -> 3962347 | E8: ='Income Statement '!E9 -> 4102108 | F8: ='Income Statement '!F9 -> 4163510 | G8: ='Income Statement '!G9 -> 4225933.6 | H8: ='Income Statement '!H9 -> 4289397.2 | I8: ='Income Statement '!I9 -> 4353919.6 | J8: ='Income Statement '!J9 -> 4419519.7
B9: Cost of Sales | D9: =-'Income Statement '!D11 -> 1752337 | E9: =-'Income Statement '!E11 -> 1691850 | F9: =-'Income Statement '!F11 -> 1873579.5 | G9: =-'Income Statement '!G11 -> 1901670.1 | H9: =-'Income Statement '!H11 -> 1930228.7 | I9: =-'Income Statement '!I11 -> 1959263.8 | J9: =-'Income Statement '!J11 -> 1988783.9
B11: WORKING CAPITAL ACCOUNTS
B12: Accounts Receivable | D12: ='Balance Sheet '!D9 -> 326818 | E12: ='Balance Sheet '!E9 -> 279861 | F12: =F30*F8/Days -> 313730.09 | G12: =G30*G8/Days -> 303371.35 | H12: =H30*H8/Days -> 315571.63 | I12: =I30*I8/Days -> 316438.88 | J12: =J30*J8/Days -> 323175.7
B13: Inventories | D13: ='Balance Sheet '!D10 -> 385054 | E13: ='Balance Sheet '!E10 -> 356254 | F13: =F31*F9/Days -> 403108.21 | G13: =G31*G9/Days -> 404793.99 | H13: =H31*H9/Days -> 413084.79 | I13: =I31*I9/Days -> 418176.02 | J13: =J31*J9/Days -> 425046.35
B14: Prepaid Expenses | D14: ='Balance Sheet '!D11 -> 45129 | E14: ='Balance Sheet '!E11 -> 51623 | F14: =F8*F32 -> 49907.926 | G14: =G8*G32 -> 51918.74 | H14: =H8*H32 -> 52057.686 | I14: =I8*I32 -> 53165.948 | J14: =J8*J32 -> 53801.947
B15: Other Current Assets | D15: ='Balance Sheet '!D12 -> 35859 | E15: ='Balance Sheet '!E12 -> 28253 | F15: =F8*F33 -> 33177.707 | G15: =G8*G33 -> 31390.491 | H15: =H8*H33 -> 33021.383 | I15: =I8*I33 -> 32929.64 | J15: =J8*J33 -> 33724.451
B16: Total Noncash Working Capital Assets | D16: =SUM(D12:D15) -> 792860 | E16: =SUM(E12:E15) -> 715991 | F16: =SUM(F12:F15) -> 799923.93 | G16: =SUM(G12:G15) -> 791474.57 | H16: =SUM(H12:H15) -> 813735.48 | I16: =SUM(I12:I15) -> 820710.49 | J16: =SUM(J12:J15) -> 835748.45
B18: Accounts Payable | D18: ='Balance Sheet '!D21 -> 260978 | E18: ='Balance Sheet '!E21 -> 264901 | F18: =F35*F9/Days -> 286195.03 | G18: =G35*G9/Days -> 294119.75 | H18: =H35*H9/Days -> 296692.56 | I18: =I35*I9/Days -> 302091.45 | J18: =J35*J9/Days -> 306168.01
B19: Accrued Expenses and Other Current Liabilities | D19: ='Balance Sheet '!D22 -> 413990 | E19: ='Balance Sheet '!E22 -> 475307 | F19: =F8*F36 -> 458714.65 | G19: =G8*G36 -> 477623.36 | H19: =H8*H36 -> 478690.21 | I19: =I8*I36 -> 488989.69 | J19: =J8*J36 -> 494784.47
F20: =F8*F37 -> 0 | G20: =G8*G37 -> 0 | H20: =H8*H37 -> 0 | I20: =I8*I37 -> 0 | J20: =J8*J37 -> 0
B21: Total Working Capital liabilities | D21: =SUM(D18:D20) -> 674968 | E21: =SUM(E18:E20) -> 740208 | F21: =SUM(F18:F20) -> 744909.68 | G21: =SUM(G18:G20) -> 771743.1 | H21: =SUM(H18:H20) -> 775382.77 | I21: =SUM(I18:I20) -> 791081.15 | J21: =SUM(J18:J20) -> 800952.48
B28: RATIOS/ASSUMPTIONS
B29: Number of days/year | C29: 365
B30: Accounts Receivable (A/R days) | D30: =D12/D8*Days -> 30.105533 | E30: =E12/E8*Days -> 24.901652 | F30: =AVERAGE(D30:E30) -> 27.503593 | G30: =AVERAGE(E30:F30) -> 26.202622 | H30: =AVERAGE(F30:G30) -> 26.853107 | I30: =AVERAGE(G30:H30) -> 26.527865 | J30: =AVERAGE(H30:I30) -> 26.690486
B31: Inventory (inventory days) | D31: =D13/D9*Days -> 80.204156 | E31: =E13/E9*Days -> 76.858297 | F31: =AVERAGE(D31:E31) -> 78.531227 | G31: =AVERAGE(E31:F31) -> 77.694762 | H31: =AVERAGE(F31:G31) -> 78.112994 | I31: =AVERAGE(G31:H31) -> 77.903878 | J31: =AVERAGE(H31:I31) -> 78.008436
B32: Prepaid Expenses (% Total Revenue) | D32: =D14/D8 -> 0.011389462 | E32: =E14/E8 -> 0.012584505 | F32: =AVERAGE(D32:E32) -> 0.011986984 | G32: =AVERAGE(E32:F32) -> 0.012285744 | H32: =AVERAGE(F32:G32) -> 0.012136364 | I32: =AVERAGE(G32:H32) -> 0.012211054 | J32: =AVERAGE(H32:I32) -> 0.012173709
B33: Other Current Assets (% Total Revenue) | D33: =D15/D8 -> 0.0090499393 | E33: =E15/E8 -> 0.0068874345 | F33: =AVERAGE(D33:E33) -> 0.0079686869 | G33: =AVERAGE(E33:F33) -> 0.0074280607 | H33: =AVERAGE(F33:G33) -> 0.0076983738 | I33: =AVERAGE(G33:H33) -> 0.0075632172 | J33: =AVERAGE(H33:I33) -> 0.0076307955
B35: Accounts Payable (A/P days) | D35: =D18/D9*Days -> 54.35996 | E35: =E18/E9*Days -> 57.149786 | F35: =AVERAGE(D35:E35) -> 55.754873 | G35: =AVERAGE(E35:F35) -> 56.452329 | H35: =AVERAGE(F35:G35) -> 56.103601 | I35: =AVERAGE(G35:H35) -> 56.277965 | J35: =AVERAGE(H35:I35) -> 56.190783
B36: Accrued expenses (% Total Revenue) | D36: =D19/D8 -> 0.10448101 | E36: =E19/E8 -> 0.11586896 | F36: =AVERAGE(D36:E36) -> 0.11017498 | G36: =AVERAGE(E36:F36) -> 0.11302197 | H36: =AVERAGE(F36:G36) -> 0.11159848 | I36: =AVERAGE(G36:H36) -> 0.11231023 | J36: =AVERAGE(H36:I36) -> 0.11195435
B37: Deferred Revenue, Current (% Total Revenue) | D37: =D20/D8 -> 0 | E37: =E20/E8 -> 0 | F37: =AVERAGE(D37:E37) -> 0 | G37: =AVERAGE(E37:F37) -> 0 | H37: =AVERAGE(F37:G37) -> 0 | I37: =AVERAGE(G37:H37) -> 0 | J37: =AVERAGE(H37:I37) -> 0

Sheet PPE Schedule
B2: ='Assumptions '!C5 &" PPE Schedule" -> CROCS, INC. PPE Schedule
B3: ='Assumptions '!B3 -> (Dollars in Thousands Except Per Share Data)
F6: =G6-1 -> 2023 | G6: =H6-1 -> 2024 | H6: =H24 -> 2025 | I6: =I24 -> 2026 | J6: =J24 -> 2027 | K6: =K24 -> 2028 | L6: =L24 -> 2029
B7: Beginning Balance - PPE | H7: =G10 -> 244335 | I7: =H10 -> 282885.72 | J7: =I10 -> 302407.68 | K7: =J10 -> 321583.85 | L7: =K10 -> 330785.44
B8: Add: CAPEX (from CFI 2024, 10K ) | F8: 115625 | G8: 69347 | H8: =H12*'Income Statement '!F9 -> 95940.069 | I8: =I12*'Income Statement '!G9 -> 84409.399 | J8: =J12*'Income Statement '!H9 -> 92258.964 | K8: =K12*'Income Statement '!I9 -> 90306.28 | L8: =L12*'Income Statement '!J9 -> 93362.317
B9: Less: D&A - PPE (from 10K ) | F9: -32415 | G9: -46772 | H9: =-H31 -> -57389.352 | I9: =-I31 -> -64887.435 | J9: =-J31 -> -73082.794 | K9: =-K31 -> -81104.697 | L9: =-L31 -> -89398.067
B10: Ending Balance - PPE | F10: ='Balance Sheet '!D13 -> 238315 | G10: ='Balance Sheet '!E13 -> 244335 | H10: =SUM(H7:H9) -> 282885.72 | I10: =SUM(I7:I9) -> 302407.68 | J10: =SUM(J7:J9) -> 321583.85 | K10: =SUM(K7:K9) -> 330785.44 | L10: =SUM(L7:L9) -> 334749.69
B12: CAPEX as % of Total Revenue | F12: =F8/'Income Statement '!D9 -> 0.029180937 | G12: =G8/'Income Statement '!E9 -> 0.016905211 | H12: =AVERAGE(F12:G12) -> 0.023043074 | I12: =AVERAGE(G12:H12) -> 0.019974142 | J12: =AVERAGE(H12:I12) -> 0.021508608 | K12: =AVERAGE(I12:J12) -> 0.020741375 | L12: =AVERAGE(J12:K12) -> 0.021124992
B15: Gross PPE (from 10K) | G15: 397790
B16: Non-Depreciable PPE (land)
B17: Accumulated Depreciation & Amortization | G17: 153455
B18: Net Depreciable PPE | G18: =G15-G16-G17 -> 244335
B20: Average Useful Life | G20: =-(G15-G16)/AVERAGE('Income Statement '!C15:E15) -> 11.257464
C24: Cost | D24: Salvage | E24: Life | H24: ='Assumptions '!D12 -> 2025 | I24: =H24+1 -> 2026 | J24: =I24+1 -> 2027 | K24: =J24+1 -> 2028 | L24: =K24+1 -> 2029
B25: =H24&" Existing PPE" -> 2025 Existing PPE | C25: =G18 -> 244335 | D25: 0 | E25: 5 | G25: =LEFT(B25,4)*1 -> 2025 | H25: =IF(AND($G25<=H$24, $G25+$E25>H$24),SLN($C25,$C25*$D25,$E25), 0) -> 48867 | I25: =IF(AND($G25<=I$24, $G25+$E25>I$24),SLN($C25,$C25*$D25,$E25), 0) -> 48867 | J25: =IF(AND($G25<=J$24, $G25+$E25>J$24),SLN($C25,$C25*$D25,$E25), 0) -> 48867 | K25: =IF(AND($G25<=K$24, $G25+$E25>K$24),SLN($C25,$C25*$D25,$E25), 0) -> 48867 | L25: =IF(AND($G25<=L$24, $G25+$E25>L$24),SLN($C25,$C25*$D25,$E25), 0) -> 48867
B26: =H24&" CAPEX" -> 2025 CAPEX | C26: {=TRANSPOSE(H8:L8)} -> 95940.069 | D26: 0 | E26: =$G$20 -> 11.257464 | G26: =LEFT(B26,4)*1 -> 2025 | H26: =IF(AND($G26<=H$24, $G26+$E26>H$24),SLN($C26,$C26*$D26,$E26), 0) -> 8522.3517 | I26: =IF(AND($G26<=I$24, $G26+$E26>I$24),SLN($C26,$C26*$D26,$E26), 0) -> 8522.3517 | J26: =IF(AND($G26<=J$24, $G26+$E26>J$24),SLN($C26,$C26*$D26,$E26), 0) -> 8522.3517 | K26: =IF(AND($G26<=K$24, $G26+$E26>K$24),SLN($C26,$C26*$D26,$E26), 0) -> 8522.3517 | L26: =IF(AND($G26<=L$24, $G26+$E26>L$24),SLN($C26,$C26*$D26,$E26), 0) -> 8522.3517
B27: =I24&" CAPEX" -> 2026 CAPEX | C27: 84409.399 | D27: 0 | E27: =$G$20 -> 11.257464 | G27: =LEFT(B27,4)*1 -> 2026 | H27: =IF(AND($G27<=H$24, $G27+$E27>H$24),SLN($C27,$C27*$D27,$E27), 0) -> 0 | I27: =IF(AND($G27<=I$24, $G27+$E27>I$24),SLN($C27,$C27*$D27,$E27), 0) -> 7498.0829 | J27: =IF(AND($G27<=J$24, $G27+$E27>J$24),SLN($C27,$C27*$D27,$E27), 0) -> 7498.0829 | K27: =IF(AND($G27<=K$24, $G27+$E27>K$24),SLN($C27,$C27*$D27,$E27), 0) -> 7498.0829 | L27: =IF(AND($G27<=L$24, $G27+$E27>L$24),SLN($C27,$C27*$D27,$E27), 0) -> 7498.0829
B28: =J24&" CAPEX" -> 2027 CAPEX | C28: 92258.964 | D28: 0 | E28: =$G$20 -> 11.257464 | G28: =LEFT(B28,4)*1 -> 2027 | H28: =IF(AND($G28<=H$24, $G28+$E28>H$24),SLN($C28,$C28*$D28,$E28), 0) -> 0 | I28: =IF(AND($G28<=I$24, $G28+$E28>I$24),SLN($C28,$C28*$D28,$E28), 0) -> 0 | J28: =IF(AND($G28<=J$24, $G28+$E28>J$24),SLN($C28,$C28*$D28,$E28), 0) -> 8195.3594 | K28: =IF(AND($G28<=K$24, $G28+$E28>K$24),SLN($C28,$C28*$D28,$E28), 0) -> 8195.3594 | L28: =IF(AND($G28<=L$24, $G28+$E28>L$24),SLN($C28,$C28*$D28,$E28), 0) -> 8195.3594
B29: =K24&" CAPEX" -> 2028 CAPEX | C29: 90306.28 | D29: 0 | E29: =$G$20 -> 11.257464 | G29: =LEFT(B29,4)*1 -> 2028 | H29: =IF(AND($G29<=H$24, $G29+$E29>H$24),SLN($C29,$C29*$D29,$E29), 0) -> 0 | I29: =IF(AND($G29<=I$24, $G29+$E29>I$24),SLN($C29,$C29*$D29,$E29), 0) -> 0 | J29: =IF(AND($G29<=J$24, $G29+$E29>J$24),SLN($C29,$C29*$D29,$E29), 0) -> 0 | K29: =IF(AND($G29<=K$24, $G29+$E29>K$24),SLN($C29,$C29*$D29,$E29), 0) -> 8021.9025 | L29: =IF(AND($G29<=L$24, $G29+$E29>L$24),SLN($C29,$C29*$D29,$E29), 0) -> 8021.9025
B30: =L24&" CAPEX" -> 2029 CAPEX | C30: 93362.317 | D30: 0 | E30: =$G$20 -> 11.257464 | G30: =LEFT(B30,4)*1 -> 2029 | H30: =IF(AND($G30<=H$24, $G30+$E30>H$24),SLN($C30,$C30*$D30,$E30), 0) -> 0 | I30: =IF(AND($G30<=I$24, $G30+$E30>I$24),SLN($C30,$C30*$D30,$E30), 0) -> 0 | J30: =IF(AND($G30<=J$24, $G30+$E30>J$24),SLN($C30,$C30*$D30,$E30), 0) -> 0 | K30: =IF(AND($G30<=K$24, $G30+$E30>K$24),SLN($C30,$C30*$D30,$E30), 0) -> 0 | L30: =IF(AND($G30<=L$24, $G30+$E30>L$24),SLN($C30,$C30*$D30,$E30), 0) -> 8293.3702
H31: =SUM(H25:H30) -> 57389.352 | I31: =SUM(I25:I30) -> 64887.435 | J31: =SUM(J25:J30) -> 73082.794 | K31: =SUM(K25:K30) -> 81104.697 | L31: =SUM(L25:L30) -> 89398.067
