Workbook

Sheet Assumptions
A1: =D6 -> Abercrombie & Fitch Co.
A4: Model Settings
A6: Company Name | D6: Abercrombie & Fitch Co.
A7: Ticker | D7: ANF
A8: Financial Format (0 = Thousands, 1= Millions) | D8: 0
A9: Last Year of Audited Financials | D9: 2016
A10: Future Performance Senario | D10: Best Case
A11: Circularity Breaker (0= Off; 1 = On) | D11: 0
E13: Best Case | K13: Base Case | Q13: Worst Case
A15: Income statement assumptions
E17: =$D$9+1 -> 2017 | F17: =E17+1 -> 2018 | G17: =F17+1 -> 2019 | H17: =G17+1 -> 2020 | I17: =H17+1 -> 2021 | K17: =E17 -> 2017 | L17: =F17 -> 2018 | M17: =G17 -> 2019 | N17: =H17 -> 2020 | O17: =I17 -> 2021 | Q17: =E17 -> 2017 | R17: =F17 -> 2018 | S17: =G17 -> 2019 | T17: =H17 -> 2020 | U17: =I17 -> 2021
A18: Net sales (growth %) | E18: -0.01 | F18: 0 | G18: 0.005 | H18: 0.01 | I18: 0.015 | K18: -0.03 | L18: -0.02 | M18: -0.01 | N18: -0.01 | O18: -0.01 | Q18: -0.04 | R18: -0.03 | S18: -0.02 | T18: -0.02 | U18: -0.02
A19: Operational expenses
A20: Cost of sales (as a % of Net Sales) | E20: 0.385 | F20: 0.385 | G20: 0.385 | H20: 0.385 | I20: 0.385 | K20: 0.39 | L20: 0.39 | M20: 0.39 | N20: 0.39 | O20: 0.39 | Q20: 0.3925 | R20: 0.3925 | S20: 0.3925 | T20: 0.3925 | U20: 0.3925
A21: Stores and distribution expense (as a % of Net Sales) | E21: 0.475 | F21: 0.475 | G21: 0.475 | H21: 0.475 | I21: 0.475 | K21: 0.48 | L21: 0.48 | M21: 0.48 | N21: 0.48 | O21: 0.48 | Q21: 0.4825 | R21: 0.4825 | S21: 0.4825 | T21: 0.4825 | U21: 0.4825
A22: Marketing, research and general expenses (as a % of Net Sales) | E22: 0.06 | F22: 0.06 | G22: 0.06 | H22: 0.06 | I22: 0.06 | K22: 0.0625 | L22: 0.0625 | M22: 0.0625 | N22: 0.0625 | O22: 0.0625 | Q22: 0.065 | R22: 0.065 | S22: 0.065 | T22: 0.065 | U22: 0.065
A23: Other operating (income) expense, net (as a % of Net Sales) | E23: -0.005 | F23: -0.005 | G23: -0.005 | H23: -0.005 | I23: -0.005 | K23: -0.001 | L23: -0.001 | M23: -0.001 | N23: -0.001 | O23: -0.001 | Q23: 0.001 | R23: 0.001 | S23: 0.001 | T23: 0.001 | U23: 0.001
A24: Interest income ($ 000) | E24: See debt schedule | K24: See debt schedule | Q24: See debt schedule
A25: Interest expense ($ 000)
A27: Effective Tax Rate | E27: 0.21 | F27: 0.21 | G27: 0.21 | H27: 0.21 | I27: 0.21 | K27: 0.21 | L27: 0.21 | M27: 0.21 | N27: 0.21 | O27: 0.21 | Q27: 0.21 | R27: 0.21 | S27: 0.21 | T27: 0.21 | U27: 0.21
A28: Net Income attributable to non-controlling interests (as % of Net Income including non-controlling interests) | E28: 0.08 | F28: 0.08 | G28: 0.08 | H28: 0.08 | I28: 0.08 | K28: 0.08 | L28: 0.08 | M28: 0.08 | N28: 0.08 | O28: 0.08 | Q28: 0.08 | R28: 0.08 | S28: 0.08 | T28: 0.08 | U28: 0.08
A29: Projected Shares Outstanding (000s) | E29: 68100 | F29: 68100 | G29: 68100 | H29: 68100 | I29: 68100 | K29: 68100 | L29: 68100 | M29: 68100 | N29: 68100 | O29: 68100 | Q29: 68100 | R29: 68100 | S29: 68100 | T29: 68100 | U29: 68100
A31: Balance Sheet Assumptions
E33: =E17 -> 2017 | F33: =F17 -> 2018 | G33: =G17 -> 2019 | H33: =H17 -> 2020 | I33: =I17 -> 2021 | K33: =K17 -> 2017 | L33: =L17 -> 2018 | M33: =M17 -> 2019 | N33: =N17 -> 2020 | O33: =O17 -> 2021 | Q33: =Q17 -> 2017 | R33: =R17 -> 2018 | S33: =S17 -> 2019 | T33: =T17 -> 2020 | U33: =U17 -> 2021
A34: Assets
A35: Current Assets
A36: Cash and cash equivalents | E36: As per Schedule. See below for minimum requirements. | K36: As per Schedule. See below for minimum requirements. | Q36: As per Schedule. See below for minimum requirements.
A37: Accounts receivable (DAYS) | E37: As per Working capital Schedule | K37: As per Working capital Schedule | Q37: As per Working capital Schedule
A38: Inventories (DAYS)
A39: Other current assets
A41: Non-Current Assets
A42: Property, plant and equipment, net | E42: See fixed asset schedule | K42: See fixed asset schedule | Q42: See fixed asset schedule
A43: Other Assets ($ 000) | E43: 207774 | F43: 227554 | G43: 233282 | H43: 222870 | I43: 227902 | K43: 207774 | L43: 227554 | M43: 233282 | N43: 222870 | O43: 227902 | Q43: 207774 | R43: 227554 | S43: 233282 | T43: 222870 | U43: 227902
A45: Liabilities
A46: Current Liabilities
A47: Accounts payable (DAYS) | E47: As per working capital schedule | K47: As per working capital schedule | Q47: As per working capital schedule
A48: Accrued expenses
A49: Accrued income taxes
A50: Other current liabilities
A51: Current portion long-term debt ($ 000) | E51: 0 | F51: 68566 | G51: 0 | H51: 50000 | I51: 0 | K51: 0 | L51: 68566 | M51: 0 | N51: 50000 | O51: 0 | Q51: 0 | R51: 68566 | S51: 0 | T51: 50000 | U51: 0
...

Sheet Income Statement
A1: =Assumptions!D6 -> Abercrombie & Fitch Co.
A3: Consolidated Statements of Income
A4: ="(Dollars in "&IF(Assumptions!$D$8=0,"Thousands","Millions")&" Except Per Share Data)" -> (Dollars in Thousands Except Per Share Data)
B6: =+C6-1 -> 2014 | C6: =D6-1 -> 2015 | D6: =Assumptions!$D$9 -> 2016 | E6: =Assumptions!E17 -> 2017 | F6: =Assumptions!F17 -> 2018 | G6: =Assumptions!G17 -> 2019 | H6: =Assumptions!H17 -> 2020 | I6: =Assumptions!I17 -> 2021
A7: Net sales | B7: 3744030 | C7: 3518680 | D7: 3326740 | E7: =D7*(1+Assumptions!E68) -> 3293472.6 | F7: =E7*(1+Assumptions!F68) -> 3293472.6 | G7: =F7*(1+Assumptions!G68) -> 3309940 | H7: =G7*(1+Assumptions!H68) -> 3343039.4 | I7: =H7*(1+Assumptions!I68) -> 3393185
A8: Cost of sales | B8: -1430460 | C8: -1361137 | D8: -1298172 | E8: =-E7*Assumptions!E70 -> -1267987 | F8: =-F7*Assumptions!F70 -> -1267987 | G8: =-G7*Assumptions!G70 -> -1274326.9 | H8: =-H7*Assumptions!H70 -> -1287070.2 | I8: =-I7*Assumptions!I70 -> -1306376.2
A9: Gross profit | B9: 2313570 | C9: 2157543 | D9: 2028568 | E9: =E7+E8 -> 2025485.6 | F9: =F7+F8 -> 2025485.6 | G9: =G7+G8 -> 2035613.1 | H9: =H7+H8 -> 2055969.2 | I9: =I7+I8 -> 2086808.7
A10: Stores and distribution expense | B10: -1703051 | C10: -1604214 | D10: -1578460 | E10: =-E7*Assumptions!E71 -> -1564399.5 | F10: =-F7*Assumptions!F71 -> -1564399.5 | G10: =-G7*Assumptions!G71 -> -1572221.5 | H10: =-H7*Assumptions!H71 -> -1587943.7 | I10: =-I7*Assumptions!I71 -> -1611762.9
A11: Marketing, research and general expenses | B11: -232399 | C11: -256641 | D11: -257788 | E11: =-E7*Assumptions!E72 -> -197608.36 | F11: =-F7*Assumptions!F72 -> -197608.36 | G11: =-G7*Assumptions!G72 -> -198596.4 | H11: =-H7*Assumptions!H72 -> -200582.36 | I11: =-I7*Assumptions!I72 -> -203591.1
A12: Depreciation and amortization | B12: -226421 | C12: -213680 | D12: -195414 | E12: ='Fixed Asset Schedule'!G20 -> -178247.6 | F12: ='Fixed Asset Schedule'!H20 -> -191072.6 | G12: ='Fixed Asset Schedule'!I20 -> -199305.93 | H12: ='Fixed Asset Schedule'!J20 -> -207539.27 | I12: ='Fixed Asset Schedule'!K20 -> -215772.6
A13: Other operating income (expense), net | B13: -38180 | C13: -10170 | D13: 18282 | E13: =-E7*Assumptions!E73 -> 16467.363 | F13: =-F7*Assumptions!F73 -> 16467.363 | G13: =-G7*Assumptions!G73 -> 16549.7 | H13: =-H7*Assumptions!H73 -> 16715.197 | I13: =-I7*Assumptions!I73 -> 16965.925
A14: Operating income | B14: 113519 | C14: 72838 | D14: 15188 | E14: =SUM(E9:E13) -> 101697.57 | F14: =SUM(F9:F13) -> 88872.571 | G14: =SUM(G9:G13) -> 82038.964 | H14: =SUM(H9:H13) -> 76619.079 | I14: =SUM(I9:I13) -> 72648.121
A15: Interest income | B15: 3500 | C15: 4353 | D15: 3744 | E15: =IF(Assumptions!$D$11=0,'Debt & Shareholder Schedule'!E45,0) -> 11037.163 | F15: =IF(Assumptions!$D$11=0,'Debt & Shareholder Schedule'!F45,0) -> 14689.723 | G15: =IF(Assumptions!$D$11=0,'Debt & Shareholder Schedule'!G45,0) -> 15810.207 | H15: =IF(Assumptions!$D$11=0,'Debt & Shareholder Schedule'!H45,0) -> 17196.508 | I15: =IF(Assumptions!$D$11=0,'Debt & Shareholder Schedule'!I45,0) -> 18922.922
A16: Interest expense | B16: -17865 | C16: -22601 | D16: -22410 | E16: =IF(Assumptions!$D$11=0,-'Debt & Shareholder Schedule'!E40,0) -> -13147.889 | F16: =IF(Assumptions!$D$11=0,-'Debt & Shareholder Schedule'!F40,0) -> -16065.389 | G16: =IF(Assumptions!$D$11=0,-'Debt & Shareholder Schedule'!G40,0) -> -14731.78 | H16: =IF(Assumptions!$D$11=0,-'Debt & Shareholder Schedule'!H40,0) -> -13398.171 | I16: =IF(Assumptions!$D$11=0,-'Debt & Shareholder Schedule'!I40,0) -> -12425.671
A17: Income before taxes | B17: 99154 | C17: 54590 | D17: =SUM(D14:D16) -> -3478 | E17: =SUM(E14:E16) -> 99586.845 | F17: =SUM(F14:F16) -> 87496.906 | G17: =SUM(G14:G16) -> 83117.39 | H17: =SUM(H14:H16) -> 80417.416 | I17: =SUM(I14:I16) -> 79145.372
A18: Tax expense | B18: -47333 | C18: -16031 | D18: 11196 | E18: =-E17*Assumptions!E77 -> -20913.237 | F18: =-F17*Assumptions!F77 -> -18374.35 | G18: =-G17*Assumptions!G77 -> -17454.652 | H18: =-H17*Assumptions!H77 -> -16887.657 | I18: =-I17*Assumptions!I77 -> -16620.528
A19: Net income including non-controlling interests | B19: 51821 | C19: 38559 | D19: 7718 | E19: =SUM(E17:E18) -> 78673.607 | F19: =SUM(F17:F18) -> 69122.555 | G19: =SUM(G17:G18) -> 65662.738 | H19: =SUM(H17:H18) -> 63529.759 | I19: =SUM(I17:I18) -> 62524.844
A20: Less: Net Income attributable to non-controlling interests | B20: 0 | C20: -2983 | D20: -3762 | E20: =-E19*Assumptions!E78 -> -6293.8886 | F20: =-F19*Assumptions!F78 -> -5529.8044 | G20: =-G19*Assumptions!G78 -> -5253.0191 | H20: =-H19*Assumptions!H78 -> -5082.3807 | I20: =-I19*Assumptions!I78 -> -5001.9875
A21: Net Income attributable to ANF | B21: 51821 | C21: 35576 | D21: =D19+D20 -> 3956 | E21: =SUM(E19:E20) -> 72379.719 | F21: =SUM(F19:F20) -> 63592.751 | G21: =SUM(G19:G20) -> 60409.719 | H21: =SUM(H19:H20) -> 58447.378 | I21: =SUM(I19:I20) -> 57522.856

Sheet Balance Sheet
A1: =Assumptions!D6 -> Abercrombie & Fitch Co.
A3: Balance Sheet
A4: ="(Dollars in "&IF(Assumptions!$D$8=0,"Thousands","Millions")&")" -> (Dollars in Thousands)
A6: Assets | B6: ='Income Statement'!B6 -> 2014 | C6: ='Income Statement'!C6 -> 2015 | D6: ='Income Statement'!D6 -> 2016 | E6: ='Income Statement'!E6 -> 2017 | F6: ='Income Statement'!F6 -> 2018 | G6: ='Income Statement'!G6 -> 2019 | H6: ='Income Statement'!H6 -> 2020 | I6: ='Income Statement'!I6 -> 2021
A7: Current Assets
A8: Cash and cash equivalents | B8: 520708 | C8: 588578 | D8: 547189 | E8: =SCF!B36 -> 924432.69 | F8: =SCF!C36 -> 1034197.1 | G8: =SCF!D36 -> 1073830.5 | H8: =SCF!E36 -> 1219037.3 | I8: =SCF!F36 -> 1304019
A9: Receivables | B9: 52910 | C9: 56868 | D9: 93384 | E9: ='WC Schedule'!F11 -> 64158.168 | F9: ='WC Schedule'!G11 -> 70029.957 | G9: ='WC Schedule'!H11 -> 76008.677 | H9: ='WC Schedule'!I11 -> 70798.172 | I9: ='WC Schedule'!J11 -> 74042.495
A10: Inventories | B10: 460794 | C10: 436701 | D10: 399795 | E10: ='WC Schedule'!F12 -> 402280.19 | F10: ='WC Schedule'!G12 -> 400221.4 | G10: ='WC Schedule'!H12 -> 400013.59 | H10: ='WC Schedule'!I12 -> 405087.83 | I10: ='WC Schedule'!J12 -> 411567.65
A11: Other current assets | B11: 130560 | C11: 96833 | D11: 98932 | E11: ='WC Schedule'!F13 -> 101142.14 | F11: ='WC Schedule'!G13 -> 96573.394 | G11: ='WC Schedule'!H13 -> 99045.502 | H11: ='WC Schedule'!I13 -> 100242.37 | I11: ='WC Schedule'!J13 -> 100926.58
A12: Total Current Assets | B12: 1164972 | C12: 1178980 | D12: 1139300 | E12: =SUM(E8:E11) -> 1492013.2 | F12: =SUM(F8:F11) -> 1601021.8 | G12: =SUM(G8:G11) -> 1648898.3 | H12: =SUM(H8:H11) -> 1795165.6 | I12: =SUM(I8:I11) -> 1890555.7
A14: Non-Current Assets
A15: Property, plant and equipment, net | B15: 967001 | C15: 894178 | D15: 824738 | E15: ='Fixed Asset Schedule'!G21 -> 786490.4 | F15: ='Fixed Asset Schedule'!H21 -> 730417.8 | G15: ='Fixed Asset Schedule'!I21 -> 661111.87 | H15: ='Fixed Asset Schedule'!J21 -> 583572.6 | I15: ='Fixed Asset Schedule'!K21 -> 497800
A16: Other assets | B16: 373194 | C16: 359881 | D16: 331719 | E16: =Assumptions!E93 -> 207774 | F16: =Assumptions!F93 -> 227554 | G16: =Assumptions!G93 -> 233282 | H16: =Assumptions!H93 -> 222870 | I16: =Assumptions!I93 -> 227902
A17: Total Non-Current Assets | B17: 1340195 | C17: 1254059 | D17: 1156457 | E17: =SUM(E15:E16) -> 994264.4 | F17: =SUM(F15:F16) -> 957971.8 | G17: =SUM(G15:G16) -> 894393.87 | H17: =SUM(H15:H16) -> 806442.6 | I17: =SUM(I15:I16) -> 725702
A19: Total Assets | B19: 2505167 | C19: 2433039 | D19: 2295757 | E19: =SUM(E12,E17) -> 2486277.6 | F19: =SUM(F12,F17) -> 2558993.6 | G19: =SUM(G12,G17) -> 2543292.1 | H19: =SUM(H12,H17) -> 2601608.2 | I19: =SUM(I12,I17) -> 2616257.7
A21: Liabilities
A22: Current Liabilities
A23: Accounts payable | B23: 141685 | C23: 184175 | D23: 187017 | E23: ='WC Schedule'!F16 -> 160110.71 | F23: ='WC Schedule'!G16 -> 171616.85 | G23: ='WC Schedule'!H16 -> 172490.33 | H23: ='WC Schedule'!I16 -> 169846.43 | I23: ='WC Schedule'!J16 -> 175502.53
A24: Accrued expenses | B24: 282736 | C24: 321237 | D24: 273044 | E24: ='WC Schedule'!F17 -> 273233.93 | F24: ='WC Schedule'!G17 -> 281408.08 | G24: ='WC Schedule'!H17 -> 276360.12 | H24: ='WC Schedule'!I17 -> 280704.36 | I24: ='WC Schedule'!J17 -> 286051.14
A25: Income taxes payable | B25: 32804 | C25: 5988 | D25: 5863 | E25: ='WC Schedule'!F19 -> 13421.826 | F25: ='WC Schedule'!G19 -> 8276.9812 | G25: ='WC Schedule'!H19 -> 9213.5643 | H25: ='WC Schedule'!I19 -> 10443.691 | I25: ='WC Schedule'!J19 -> 9524.4017
A26: Other current liabilities | B26: 26629 | C26: 23303 | D26: 20076 | E26: ='WC Schedule'!F18 -> 21703.743 | F26: ='WC Schedule'!G18 -> 21130.171 | G26: ='WC Schedule'!H18 -> 21007.567 | H26: ='WC Schedule'!I18 -> 21565.402 | I26: ='WC Schedule'!J18 -> 21731.564
A27: Current portion of debt | B27: 2102 | C27: 0 | D27: 0 | E27: =Assumptions!E101 -> 0 | F27: =Assumptions!F101 -> 68566 | G27: =Assumptions!G101 -> 0 | H27: =Assumptions!H101 -> 50000 | I27: =Assumptions!I101 -> 0
A28: Total Current Liabilities | B28: 485956 | C28: 534703 | D28: 486000 | E28: =SUM(E23:E27) -> 468470.21 | F28: =SUM(F23:F27) -> 550998.08 | G28: =SUM(G23:G27) -> 479071.58 | H28: =SUM(H23:H27) -> 532559.89 | I28: =SUM(I23:I27) -> 492809.63
A30: Non-Current Liabilities
A31: Revolving line of credit | B31: 0 | C31: 0 | D31: 0 | E31: ='Debt & Shareholder Schedule'!E20 -> 0 | F31: ='Debt & Shareholder Schedule'!F20 -> 0 | G31: ='Debt & Shareholder Schedule'!G20 -> 0 | H31: ='Debt & Shareholder Schedule'!H20 -> 0 | I31: ='Debt & Shareholder Schedule'!I20 -> 0
A32: Long term debt | B32: 291310 | C32: 286235 | D32: 262992 | E32: ='Debt & Shareholder Schedule'!E25-E27 -> 412992 | F32: ='Debt & Shareholder Schedule'!F25-F27 -> 344426 | G32: ='Debt & Shareholder Schedule'!G25-G27 -> 344426 | H32: ='Debt & Shareholder Schedule'!H25-H27 -> 294426 | I32: ='Debt & Shareholder Schedule'!I25-I27 -> 294426
A33: Deferred leases | B33: 156914 | C33: 136696 | D33: 122718 | E33: =Assumptions!E105*'Income Statement'!E7 -> 82336.815 | F33: =Assumptions!F105*'Income Statement'!F7 -> 82336.815 | G33: =Assumptions!G105*'Income Statement'!G7 -> 82748.499 | H33: =Assumptions!H105*'Income Statement'!H7 -> 83575.984 | I33: =Assumptions!I105*'Income Statement'!I7 -> 84829.624
A34: Other liabilities | B34: 181286 | C34: 179683 | D34: 172008 | E34: =Assumptions!E106 -> 203567 | F34: =Assumptions!F106 -> 203567 | G34: =Assumptions!G106 -> 203567 | H34: =Assumptions!H106 -> 203567 | I34: =Assumptions!I106 -> 203567
A35: Total Non-Current Liabilities | B35: 629510 | C35: 602614 | D35: 557718 | E35: =SUM(E31:E34) -> 698895.81 | F35: =SUM(F31:F34) -> 630329.81 | G35: =SUM(G31:G34) -> 630741.5 | H35: =SUM(H31:H34) -> 581568.98 | I35: =SUM(I31:I34) -> 582822.62
A37: Total Liabilities | B37: 1115466 | C37: 1137317 | D37: 1043718 | E37: =SUM(E28,E35) -> 1167366 | F37: =SUM(F28,F35) -> 1181327.9 | G37: =SUM(G28,G35) -> 1109813.1 | H37: =SUM(H28,H35) -> 1114128.9 | I37: =SUM(I28,I35) -> 1075632.3
A39: Stockholders' Equity | B39: 1389701 | C39: 1295722 | D39: 1252039 | E39: ='Debt & Shareholder Schedule'!E53 -> 1318911.6 | F39: ='Debt & Shareholder Schedule'!F53 -> 1377665.7 | G39: ='Debt & Shareholder Schedule'!G53 -> 1433479.1 | H39: ='Debt & Shareholder Schedule'!H53 -> 1487479.4 | I39: ='Debt & Shareholder Schedule'!I53 -> 1540625.5
A41: Total liabilities and stockholders' equity | B41: =B37+B39 -> 2505167 | C41: 2433039 | D41: 2295757 | E41: =SUM(E37,E39) -> 2486277.6 | F41: =SUM(F37,F39) -> 2558993.6 | G41: =SUM(G37,G39) -> 2543292.1 | H41: =SUM(H37,H39) -> 2601608.2 | I41: =SUM(I37,I39) -> 2616257.7
A43: Check | B43: =B19-B41 -> 0 | C43: =C19-C41 -> 0 | D43: =D19-D41 -> 0 | E43: =E19-E41 -> 0 | F43: =F19-F41 -> 0 | G43: =G19-G41 -> 0 | H43: =H19-H41 -> 0 | I43: =I19-I41 -> 0

Sheet SCF
A1: =Assumptions!D6 -> Abercrombie & Fitch Co.
A3: Consolidated Statement of Cash Flows
A4: ="(Dollars in "&IF(Assumptions!$D$8=0,"Thousands","Millions")&")" -> (Dollars in Thousands)
B6: ='Income Statement'!E6 -> 2017 | C6: ='Income Statement'!F6 -> 2018 | D6: ='Income Statement'!G6 -> 2019 | E6: ='Income Statement'!H6 -> 2020 | F6: ='Income Statement'!I6 -> 2021
A7: Cash Flow from Operations
A8: Net Income | B8: ='Income Statement'!E21 -> 72379.719 | C8: ='Income Statement'!F21 -> 63592.751 | D8: ='Income Statement'!G21 -> 60409.719 | E8: ='Income Statement'!H21 -> 58447.378 | F8: ='Income Statement'!I21 -> 57522.856
A9: Income (Loss) attributable to noncontrolling interests | B9: =-'Income Statement'!E20 -> 6293.8886 | C9: =-'Income Statement'!F20 -> 5529.8044 | D9: =-'Income Statement'!G20 -> 5253.0191 | E9: =-'Income Statement'!H20 -> 5082.3807 | F9: =-'Income Statement'!I20 -> 5001.9875
A10: Depreciation | B10: ='Fixed Asset Schedule'!G13 -> 178247.6 | C10: ='Fixed Asset Schedule'!H13 -> 191072.6 | D10: ='Fixed Asset Schedule'!I13 -> 199305.93 | E10: ='Fixed Asset Schedule'!J13 -> 207539.27 | F10: ='Fixed Asset Schedule'!K13 -> 215772.6
A11: (Increase) Decrease in Receivables | B11: =-('Balance Sheet'!E9-'Balance Sheet'!D9) -> 29225.832 | C11: =-('Balance Sheet'!F9-'Balance Sheet'!E9) -> -5871.7896 | D11: =-('Balance Sheet'!G9-'Balance Sheet'!F9) -> -5978.7197 | E11: =-('Balance Sheet'!H9-'Balance Sheet'!G9) -> 5210.5046 | F11: =-('Balance Sheet'!I9-'Balance Sheet'!H9) -> -3244.3223
A12: (Increase) Decrease in Inventories | B12: =-('Balance Sheet'!E10-'Balance Sheet'!D10) -> -2485.1897 | C12: =-('Balance Sheet'!F10-'Balance Sheet'!E10) -> 2058.792 | D12: =-('Balance Sheet'!G10-'Balance Sheet'!F10) -> 207.80413 | E12: =-('Balance Sheet'!H10-'Balance Sheet'!G10) -> -5074.232 | F12: =-('Balance Sheet'!I10-'Balance Sheet'!H10) -> -6479.8265
A13: (Increase) Decrease in Other current assets | B13: =-('Balance Sheet'!E11-'Balance Sheet'!D11) -> -2210.1406 | C13: =-('Balance Sheet'!F11-'Balance Sheet'!E11) -> 4568.7467 | D13: =-('Balance Sheet'!G11-'Balance Sheet'!F11) -> -2472.108 | E13: =-('Balance Sheet'!H11-'Balance Sheet'!G11) -> -1196.8682 | F13: =-('Balance Sheet'!I11-'Balance Sheet'!H11) -> -684.20583
A14: (Decrease) Increase in Accounts payable | B14: ='Balance Sheet'!E23-'Balance Sheet'!D23 -> -26906.292 | C14: ='Balance Sheet'!F23-'Balance Sheet'!E23 -> 11506.143 | D14: ='Balance Sheet'!G23-'Balance Sheet'!F23 -> 873.4789 | E14: ='Balance Sheet'!H23-'Balance Sheet'!G23 -> -2643.8987 | F14: ='Balance Sheet'!I23-'Balance Sheet'!H23 -> 5656.0961
A15: (Decrease) Increase in Accural expenses | B15: ='Balance Sheet'!E24-'Balance Sheet'!D24 -> 189.9315 | C15: ='Balance Sheet'!F24-'Balance Sheet'!E24 -> 8174.1481 | D15: ='Balance Sheet'!G24-'Balance Sheet'!F24 -> -5047.9633 | E15: ='Balance Sheet'!H24-'Balance Sheet'!G24 -> 4344.2473 | F15: ='Balance Sheet'!I24-'Balance Sheet'!H24 -> 5346.7772
A16: (Decrease) Increase in Income taxes payables | B16: ='Balance Sheet'!E25-'Balance Sheet'!D25 -> 7558.8257 | C16: ='Balance Sheet'!F25-'Balance Sheet'!E25 -> -5144.8446 | D16: ='Balance Sheet'!G25-'Balance Sheet'!F25 -> 936.58309 | E16: ='Balance Sheet'!H25-'Balance Sheet'!G25 -> 1230.127 | F16: ='Balance Sheet'!I25-'Balance Sheet'!H25 -> -919.2896
A17: (Decrease) Increase in Other current liabilities | B17: ='Balance Sheet'!E26-'Balance Sheet'!D26 -> 1627.7432 | C17: ='Balance Sheet'!F26-'Balance Sheet'!E26 -> -573.57235 | D17: ='Balance Sheet'!G26-'Balance Sheet'!F26 -> -122.60424 | E17: ='Balance Sheet'!H26-'Balance Sheet'!G26 -> 557.83563 | F17: ='Balance Sheet'!I26-'Balance Sheet'!H26 -> 166.16203
A18: Total | B18: =SUM(B8:B17) -> 263921.92 | C18: =SUM(C8:C17) -> 274912.78 | D18: =SUM(D8:D17) -> 253365.14 | E18: =SUM(E8:E17) -> 273496.74 | F18: =SUM(F8:F17) -> 278138.83
A20: Cash Flow from Investing
A21: CAPEX | B21: =-'Fixed Asset Schedule'!G19 -> -140000 | C21: =-'Fixed Asset Schedule'!H19 -> -135000 | D21: =-'Fixed Asset Schedule'!I19 -> -130000 | E21: =-'Fixed Asset Schedule'!J19 -> -130000 | F21: =-'Fixed Asset Schedule'!K19 -> -130000
A22: (Increase) Decrease in Other assets | B22: =-('Balance Sheet'!E16-'Balance Sheet'!D16) -> 123945 | C22: =-('Balance Sheet'!F16-'Balance Sheet'!E16) -> -19780 | D22: =-('Balance Sheet'!G16-'Balance Sheet'!F16) -> -5728 | E22: =-('Balance Sheet'!H16-'Balance Sheet'!G16) -> 10412 | F22: =-('Balance Sheet'!I16-'Balance Sheet'!H16) -> -5032
A23: Total | B23: =SUM(B21:B22) -> -16055 | C23: =SUM(C21:C22) -> -154780 | D23: =SUM(D21:D22) -> -135728 | E23: =SUM(E21:E22) -> -119588 | F23: =SUM(F21:F22) -> -135032
A25: Cash Flow from Financing
A26: Revolver Increases (Decreases) | B26: ='Debt & Shareholder Schedule'!E18-'Debt & Shareholder Schedule'!D20 -> 0 | C26: ='Debt & Shareholder Schedule'!F18-'Debt & Shareholder Schedule'!E20 -> 0 | D26: ='Debt & Shareholder Schedule'!G18-'Debt & Shareholder Schedule'!F20 -> 0 | E26: ='Debt & Shareholder Schedule'!H18-'Debt & Shareholder Schedule'!G20 -> 0 | F26: ='Debt & Shareholder Schedule'!I18-'Debt & Shareholder Schedule'!H20 -> 0
A27: (Dividends Paid) | B27: ='Debt & Shareholder Schedule'!E7 -> -11801.041 | C27: ='Debt & Shareholder Schedule'!F7 -> -10368.383 | D27: ='Debt & Shareholder Schedule'!G7 -> -9849.4108 | E27: ='Debt & Shareholder Schedule'!H7 -> -9529.4638 | F27: ='Debt & Shareholder Schedule'!I7 -> -9378.7265
A28: Equity Issues (Equity Repurchase) | B28: ='Debt & Shareholder Schedule'!E6 -> 0 | C28: ='Debt & Shareholder Schedule'!F6 -> 0 | D28: ='Debt & Shareholder Schedule'!G6 -> 0 | E28: ='Debt & Shareholder Schedule'!H6 -> 0 | F28: ='Debt & Shareholder Schedule'!I6 -> 0
A29: Long Term Debt Increases (Decreases) | B29: ='Debt & Shareholder Schedule'!E25-'Debt & Shareholder Schedule'!D25 -> 150000 | C29: ='Debt & Shareholder Schedule'!F25-'Debt & Shareholder Schedule'!E25 -> 0 | D29: ='Debt & Shareholder Schedule'!G25-'Debt & Shareholder Schedule'!F25 -> -68566 | E29: ='Debt & Shareholder Schedule'!H25-'Debt & Shareholder Schedule'!G25 -> 0 | F29: ='Debt & Shareholder Schedule'!I25-'Debt & Shareholder Schedule'!H25 -> -50000
A30: Deferred leases Increases (Decreases) | B30: ='Balance Sheet'!E33-'Balance Sheet'!D33 -> -40381.185 | C30: ='Balance Sheet'!F33-'Balance Sheet'!E33 -> 0 | D30: ='Balance Sheet'!G33-'Balance Sheet'!F33 -> 411.68407 | E30: ='Balance Sheet'!H33-'Balance Sheet'!G33 -> 827.48499 | F30: ='Balance Sheet'!I33-'Balance Sheet'!H33 -> 1253.6398
A31: Other Long-Term Liabilities Increases (Decreases) | B31: ='Balance Sheet'!E34-'Balance Sheet'!D34 -> 31559 | C31: ='Balance Sheet'!F34-'Balance Sheet'!E34 -> 0 | D31: ='Balance Sheet'!G34-'Balance Sheet'!F34 -> 0 | E31: ='Balance Sheet'!H34-'Balance Sheet'!G34 -> 0 | F31: ='Balance Sheet'!I34-'Balance Sheet'!H34 -> 0
A32: Total | B32: =SUM(B26:B31) -> 129376.77 | C32: =SUM(C26:C31) -> -10368.383 | D32: =SUM(D26:D31) -> -78003.727 | E32: =SUM(E26:E31) -> -8701.9788 | F32: =SUM(F26:F31) -> -58125.087
A34: Net Change in Cash | B34: =B18+B23+B32 -> 377243.69 | C34: =C18+C23+C32 -> 109764.4 | D34: =D18+D23+D32 -> 39633.416 | E34: =E18+E23+E32 -> 145206.76 | F34: =F18+F23+F32 -> 84981.748
A35: Cash at Beginning of Year | B35: ='Balance Sheet'!D8 -> 547189 | C35: =B36 -> 924432.69 | D35: =C36 -> 1034197.1 | E35: =D36 -> 1073830.5 | F35: =E36 -> 1219037.3
A36: Cash at End of Year | B36: =B34+B35 -> 924432.69 | C36: =C34+C35 -> 1034197.1 | D36: =D34+D35 -> 1073830.5 | E36: =E34+E35 -> 1219037.3 | F36: =F34+F35 -> 1304019

Sheet WC Schedule
A1: =Assumptions!D6 -> Abercrombie & Fitch Co.
A3: Working Capital Schedule
A4: ="(Dollars in "&IF(Assumptions!$D$8=0,"Thousands","Millions")&")" -> (Dollars in Thousands)
C5: ='Income Statement'!B6 -> 2014 | D5: ='Income Statement'!C6 -> 2015 | E5: ='Income Statement'!D6 -> 2016 | F5: ='Income Statement'!E6&"E" -> 2017E | G5: ='Income Statement'!F6&"E" -> 2018E | H5: ='Income Statement'!G6&"E" -> 2019E | I5: ='Income Statement'!H6&"E" -> 2020E | J5: ='Income Statement'!I6&"E" -> 2021E
A6: INCOME STATEMENT ACCOUNTS
A7: ='Income Statement'!A7 -> Net sales | C7: ='Income Statement'!B7 -> 3744030 | D7: ='Income Statement'!C7 -> 3518680 | E7: ='Income Statement'!D7 -> 3326740 | F7: ='Income Statement'!E7 -> 3293472.6 | G7: ='Income Statement'!F7 -> 3293472.6 | H7: ='Income Statement'!G7 -> 3309940 | I7: ='Income Statement'!H7 -> 3343039.4 | J7: ='Income Statement'!I7 -> 3393185
A8: Cost of Sales | C8: =-'Income Statement'!B8 -> 1430460 | D8: =-'Income Statement'!C8 -> 1361137 | E8: =-'Income Statement'!D8 -> 1298172 | F8: =-'Income Statement'!E8 -> 1267987 | G8: =-'Income Statement'!F8 -> 1267987 | H8: =-'Income Statement'!G8 -> 1274326.9 | I8: =-'Income Statement'!H8 -> 1287070.2 | J8: =-'Income Statement'!I8 -> 1306376.2
A10: WORKING CAPITAL ACCOUNTS
A11: Receivables | C11: ='Balance Sheet'!B9 -> 52910 | D11: ='Balance Sheet'!C9 -> 56868 | E11: ='Balance Sheet'!D9 -> 93384 | F11: =F29*F7/F28 -> 64158.168 | G11: =G29*G7/G28 -> 70029.957 | H11: =H29*H7/H28 -> 76008.677 | I11: =I29*I7/I28 -> 70798.172 | J11: =J29*J7/J28 -> 74042.495
A12: Inventories | C12: ='Balance Sheet'!B10 -> 460794 | D12: ='Balance Sheet'!C10 -> 436701 | E12: ='Balance Sheet'!D10 -> 399795 | F12: =F30*F8/F28 -> 402280.19 | G12: =G30*G8/G28 -> 400221.4 | H12: =H30*H8/H28 -> 400013.59 | I12: =I30*I8/I28 -> 405087.83 | J12: =J30*J8/J28 -> 411567.65
A13: Other Current Assets | C13: ='Balance Sheet'!B11 -> 130560 | D13: ='Balance Sheet'!C11 -> 96833 | E13: ='Balance Sheet'!D11 -> 98932 | F13: =F31*F7 -> 101142.14 | G13: =G31*G7 -> 96573.394 | H13: =H31*H7 -> 99045.502 | I13: =I31*I7 -> 100242.37 | J13: =J31*J7 -> 100926.58
A14: Total Noncash Working Capital Assets | C14: =SUM(C11:C13) -> 644264 | D14: =SUM(D11:D13) -> 590402 | E14: =SUM(E11:E13) -> 592111 | F14: =SUM(F11:F13) -> 567580.5 | G14: =SUM(G11:G13) -> 566824.75 | H14: =SUM(H11:H13) -> 575067.77 | I14: =SUM(I11:I13) -> 576128.37 | J14: =SUM(J11:J13) -> 586536.72
A16: Accounts Payable | C16: ='Balance Sheet'!B23 -> 141685 | D16: ='Balance Sheet'!C23 -> 184175 | E16: ='Balance Sheet'!D23 -> 187017 | F16: =F33*F8/F28 -> 160110.71 | G16: =G33*G8/G28 -> 171616.85 | H16: =H33*H8/H28 -> 172490.33 | I16: =I33*I8/I28 -> 169846.43 | J16: =J33*J8/J28 -> 175502.53
A17: Accrued Expenses | C17: ='Balance Sheet'!B24 -> 282736 | D17: ='Balance Sheet'!C24 -> 321237 | E17: ='Balance Sheet'!D24 -> 273044 | F17: =F34*F7 -> 273233.93 | G17: =G34*G7 -> 281408.08 | H17: =H34*H7 -> 276360.12 | I17: =I34*I7 -> 280704.36 | J17: =J34*J7 -> 286051.14
A18: Other Current Liabilities | C18: ='Balance Sheet'!B26 -> 26629 | D18: ='Balance Sheet'!C26 -> 23303 | E18: ='Balance Sheet'!D26 -> 20076 | F18: =F35*F7 -> 21703.743 | G18: =G35*G7 -> 21130.171 | H18: =H35*H7 -> 21007.567 | I18: =I35*I7 -> 21565.402 | J18: =J35*J7 -> 21731.564
A19: ='Balance Sheet'!A25 -> Income taxes payable | C19: ='Balance Sheet'!B25 -> 32804 | D19: ='Balance Sheet'!C25 -> 5988 | E19: ='Balance Sheet'!D25 -> 5863 | F19: =F36*F7 -> 13421.826 | G19: =G36*G7 -> 8276.9812 | H19: =H36*H7 -> 9213.5643 | I19: =I36*I7 -> 10443.691 | J19: =J36*J7 -> 9524.4017
A20: Total Working Capital liabilities | C20: =SUM(C16:C19) -> 483854 | D20: =SUM(D16:D19) -> 534703 | E20: =SUM(E16:E19) -> 486000 | F20: =SUM(F16:F19) -> 468470.21 | G20: =SUM(G16:G19) -> 482432.08 | H20: =SUM(H16:H19) -> 479071.58 | I20: =SUM(I16:I19) -> 482559.89 | J20: =SUM(J16:J19) -> 492809.63
A27: RATIOS/ASSUMPTIONS
A28: Number of days/year | C28: =_xlfn.DAYS(DATE(2015,1,1),DATE(2014,1,1)) -> 365 | D28: =_xlfn.DAYS(DATE(2016,1,1),DATE(2015,1,1)) -> 365 | E28: =_xlfn.DAYS(DATE(2017,1,1),DATE(2016,1,1)) -> 366 | F28: =_xlfn.DAYS(DATE(2018,1,1),DATE(2017,1,1)) -> 365 | G28: =_xlfn.DAYS(DATE(2019,1,1),DATE(2018,1,1)) -> 365 | H28: =_xlfn.DAYS(DATE(2020,1,1),DATE(2019,1,1)) -> 365 | I28: =_xlfn.DAYS(DATE(2021,1,1),DATE(2020,1,1)) -> 366 | J28: =_xlfn.DAYS(DATE(2022,1,1),DATE(2021,1,1)) -> 365
A29: Receivables (A/R days) | C29: =C11/C7*C28 -> 5.1581184 | D29: =D11/D7*D28 -> 5.899036 | E29: =E11/E7*E28 -> 10.273885 | F29: =AVERAGE(C29:E29) -> 7.1103464 | G29: =AVERAGE(D29:F29) -> 7.7610891 | H29: =AVERAGE(E29:G29) -> 8.3817735 | I29: =AVERAGE(F29:H29) -> 7.7510697 | J29: =AVERAGE(G29:I29) -> 7.9646441
A30: Inventory (inventory days) | C30: =C12/C8*C28 -> 117.57743 | D30: =D12/D8*D28 -> 117.10494 | E30: =E12/E8*E28 -> 112.71617 | F30: =AVERAGE(C30:E30) -> 115.79951 | G30: =AVERAGE(D30:F30) -> 115.20687 | H30: =AVERAGE(E30:G30) -> 114.57418 | I30: =AVERAGE(F30:H30) -> 115.19352 | J30: =AVERAGE(G30:I30) -> 114.99153
A31: Other Current Assets (% Net sales) | C31: =C13/C7 -> 0.034871515 | D31: =D13/D7 -> 0.027519695 | E31: =E13/E7 -> 0.029738423 | F31: =AVERAGE(C31:E31) -> 0.030709878 | G31: =AVERAGE(D31:F31) -> 0.029322665 | H31: =AVERAGE(E31:G31) -> 0.029923655 | I31: =AVERAGE(F31:H31) -> 0.029985399 | J31: =AVERAGE(G31:I31) -> 0.029743906
A33: Accounts Payable (A/P days) | C33: =C16/C8*C28 -> 36.152724 | D33: =D16/D8*D28 -> 49.38803 | E33: =E16/E8*E28 -> 52.72662 | F33: =AVERAGE(C33:E33) -> 46.089125 | G33: =AVERAGE(D33:F33) -> 49.401258 | H33: =AVERAGE(E33:G33) -> 49.405668 | I33: =AVERAGE(F33:H33) -> 48.298684 | J33: =AVERAGE(G33:I33) -> 49.035203
A34: Accrued expenses (% Net sales) | C34: =C17/C7 -> 0.075516489 | D34: =D17/D7 -> 0.091294747 | E34: =E17/E7 -> 0.082075545 | F34: =AVERAGE(C34:E34) -> 0.08296226 | G34: =AVERAGE(D34:F34) -> 0.085444184 | H34: =AVERAGE(E34:G34) -> 0.083493997 | I34: =AVERAGE(F34:H34) -> 0.083966814 | J34: =AVERAGE(G34:I34) -> 0.084301665
A35: Other Current Liabilities (% Net sales) | C35: =C18/C7 -> 0.0071123896 | D35: =D18/D7 -> 0.0066226539 | E35: =E18/E7 -> 0.0060347367 | F35: =AVERAGE(C35:E35) -> 0.0065899267 | G35: =AVERAGE(D35:F35) -> 0.0064157725 | H35: =AVERAGE(E35:G35) -> 0.006346812 | I35: =AVERAGE(F35:H35) -> 0.0064508371 | J35: =AVERAGE(G35:I35) -> 0.0064044738
A36: Accrued income taxes, current portion (% Net sales) | C36: =C19/C7 -> 0.0087616819 | D36: =D19/D7 -> 0.0017017745 | E36: =E19/E7 -> 0.001762386 | F36: =AVERAGE(C36:E36) -> 0.0040752808 | G36: =AVERAGE(D36:F36) -> 0.0025131471 | H36: =AVERAGE(E36:G36) -> 0.0027836046 | I36: =AVERAGE(F36:H36) -> 0.0031240109 | J36: =AVERAGE(G36:I36) -> 0.0028069209

Sheet Debt & Shareholder Schedule
A1: =Assumptions!D6 -> Abercrombie & Fitch Co.
A4: Debt Schedule Calculations | E4: =SCF!B6 -> 2017 | F4: =SCF!C6 -> 2018 | G4: =SCF!D6 -> 2019 | H4: =SCF!E6 -> 2020 | I4: =SCF!F6 -> 2021
A5: Cash flow available for financing | E5: =SCF!B23+SCF!B18 -> 247866.92 | F5: =SCF!C23+SCF!C18 -> 120132.78 | G5: =SCF!D23+SCF!D18 -> 117637.14 | H5: =SCF!E23+SCF!E18 -> 153908.74 | I5: =SCF!F23+SCF!F18 -> 143106.83
A6: Issuance (Repurchase) of equity | E6: =Assumptions!E110 -> 0 | F6: =Assumptions!F110 -> 0 | G6: =Assumptions!G110 -> 0 | H6: =Assumptions!H110 -> 0 | I6: =Assumptions!I110 -> 0
A7: Dividend payout | E7: =IF('Income Statement'!E19<0,0,-Assumptions!E109*'Income Statement'!E19) -> -11801.041 | F7: =IF('Income Statement'!F19<0,0,-Assumptions!F109*'Income Statement'!F19) -> -10368.383 | G7: =IF('Income Statement'!G19<0,0,-Assumptions!G109*'Income Statement'!G19) -> -9849.4108 | H7: =IF('Income Statement'!H19<0,0,-Assumptions!H109*'Income Statement'!H19) -> -9529.4638 | I7: =IF('Income Statement'!I19<0,0,-Assumptions!I109*'Income Statement'!I19) -> -9378.7265
A8: =SCF!A30 -> Deferred leases Increases (Decreases) | E8: =SCF!B30 -> -40381.185 | F8: =SCF!C30 -> 0 | G8: =SCF!D30 -> 411.68407 | H8: =SCF!E30 -> 827.48499 | I8: =SCF!F30 -> 1253.6398
A9: Other Long-Term Liabilities Increases (Decreases) | E9: ='Balance Sheet'!E34-'Balance Sheet'!D34 -> 31559 | F9: ='Balance Sheet'!F34-'Balance Sheet'!E34 -> 0 | G9: ='Balance Sheet'!G34-'Balance Sheet'!F34 -> 0 | H9: ='Balance Sheet'!H34-'Balance Sheet'!G34 -> 0 | I9: ='Balance Sheet'!I34-'Balance Sheet'!H34 -> 0
A10: Plus: Beginning cash balance | E10: ='Balance Sheet'!D8 -> 547189 | F10: ='Balance Sheet'!E8 -> 924432.69 | G10: ='Balance Sheet'!F8 -> 1034197.1 | H10: ='Balance Sheet'!G8 -> 1073830.5 | I10: ='Balance Sheet'!H8 -> 1219037.3
A11: Less: Minimum cash balance | E11: =-Assumptions!E111*'Income Statement'!E7 -> -32934.726 | F11: =-Assumptions!F111*'Income Statement'!F7 -> -32934.726 | G11: =-Assumptions!G111*'Income Statement'!G7 -> -33099.4 | H11: =-Assumptions!H111*'Income Statement'!H7 -> -33430.394 | I11: =-Assumptions!I111*'Income Statement'!I7 -> -33931.85
A12: Cash available for long term debt | E12: =SUM(E5:E11) -> 741497.97 | F12: =SUM(F5:F11) -> 1001262.4 | G12: =SUM(G5:G11) -> 1109297.1 | H12: =SUM(H5:H11) -> 1185606.9 | I12: =SUM(I5:I11) -> 1320087.2
A13: Mandatory long term debt repayment | E13: =-'Balance Sheet'!D27 -> 0 | F13: =-'Balance Sheet'!E27 -> 0 | G13: =-'Balance Sheet'!F27 -> -68566 | H13: =-'Balance Sheet'!G27 -> 0 | I13: =-'Balance Sheet'!H27 -> -50000
A14: Other long term debt issuance/(repayment) | E14: =Assumptions!E104 -> 150000 | F14: =Assumptions!F104 -> 0 | G14: =Assumptions!G104 -> 0 | H14: =Assumptions!H104 -> 0 | I14: =Assumptions!I104 -> 0
A15: Cash available for revolver | E15: =SUM(E12:E14) -> 891497.97 | F15: =SUM(F12:F14) -> 1001262.4 | G15: =SUM(G12:G14) -> 1040731.1 | H15: =SUM(H12:H14) -> 1185606.9 | I15: =SUM(I12:I14) -> 1270087.2
A17: Revolver calculation
A18: Beginning balance | E18: =D20 -> 0 | F18: =E20 -> 0 | G18: =F20 -> 0 | H18: =G20 -> 0 | I18: =H20 -> 0
A19: Issuance/(repayment) on revolver | E19: =-MIN(E18,E15) -> 0 | F19: =-MIN(F18,F15) -> 0 | G19: =-MIN(G18,G15) -> 0 | H19: =-MIN(H18,H15) -> 0 | I19: =-MIN(I18,I15) -> 0
A20: Ending balance | D20: ='Balance Sheet'!D31 -> 0 | E20: =SUM(E18,E19) -> 0 | F20: =SUM(F18,F19) -> 0 | G20: =SUM(G18,G19) -> 0 | H20: =SUM(H18,H19) -> 0 | I20: =SUM(I18,I19) -> 0
A22: Long term debt (total)
A23: Beginning balance | E23: =D25 -> 262992 | F23: =E25 -> 412992 | G23: =F25 -> 412992 | H23: =G25 -> 344426 | I23: =H25 -> 344426
A24: Total long term debt issuance/(repayment) | E24: =E13+E14 -> 150000 | F24: =F13+F14 -> 0 | G24: =G13+G14 -> -68566 | H24: =H13+H14 -> 0 | I24: =I13+I14 -> -50000
A25: Ending balance | D25: ='Balance Sheet'!D27+'Balance Sheet'!D32 -> 262992 | E25: =SUM(E23,E24) -> 412992 | F25: =SUM(F23,F24) -> 412992 | G25: =SUM(G23,G24) -> 344426 | H25: =SUM(H23,H24) -> 344426 | I25: =SUM(I23,I24) -> 294426
A28: Interest expense calculation
E29: =E4 -> 2017 | F29: =F4 -> 2018 | G29: =G4 -> 2019 | H29: =H4 -> 2020 | I29: =I4 -> 2021
A30: Revolver
A31: Average balance | E31: =AVERAGE(D20:E20) -> 0 | F31: =AVERAGE(E20:F20) -> 0 | G31: =AVERAGE(F20:G20) -> 0 | H31: =AVERAGE(G20:H20) -> 0 | I31: =AVERAGE(H20:I20) -> 0
A32: Interest rate | E32: 0.065 | F32: 0.065 | G32: 0.065 | H32: 0.065 | I32: 0.065
A33: Interest expense | E33: =E31*E32 -> 0 | F33: =F31*F32 -> 0 | G33: =G31*G32 -> 0 | H33: =H31*H32 -> 0 | I33: =I31*I32 -> 0
A35: Long term debt
A36: Average balance | E36: =AVERAGE(D25:E25) -> 337992 | F36: =AVERAGE(E25:F25) -> 412992 | G36: =AVERAGE(F25:G25) -> 378709 | H36: =AVERAGE(G25:H25) -> 344426 | I36: =AVERAGE(H25:I25) -> 319426
A37: Interest Rate | E37: 0.0389 | F37: 0.0389 | G37: 0.0389 | H37: 0.0389 | I37: 0.0389
A38: Interest expense | E38: =E36*E37 -> 13147.889 | F38: =F36*F37 -> 16065.389 | G38: =G36*G37 -> 14731.78 | H38: =H36*H37 -> 13398.171 | I38: =I36*I37 -> 12425.671
A40: Total interest expense | E40: =E33+E38 -> 13147.889 | F40: =F33+F38 -> 16065.389 | G40: =G33+G38 -> 14731.78 | H40: =H33+H38 -> 13398.171 | I40: =I33+I38 -> 12425.671
A42: Cash
A43: Average balance | E43: =AVERAGE('Balance Sheet'!D8:E8) -> 735810.85 | F43: =AVERAGE('Balance Sheet'!E8:F8) -> 979314.89 | G43: =AVERAGE('Balance Sheet'!F8:G8) -> 1054013.8 | H43: =AVERAGE('Balance Sheet'!G8:H8) -> 1146433.9 | I43: =AVERAGE('Balance Sheet'!H8:I8) -> 1261528.1
A44: Interest rate | E44: 0.015 | F44: 0.015 | G44: 0.015 | H44: 0.015 | I44: 0.015
A45: Interest income | E45: =E43*E44 -> 11037.163 | F45: =F43*F44 -> 14689.723 | G45: =G43*G44 -> 15810.207 | H45: =H43*H44 -> 17196.508 | I45: =I43*I44 -> 18922.922
A47: Shareholders' Equity Schedule | E47: =E29 -> 2017 | F47: =F29 -> 2018 | G47: =G29 -> 2019 | H47: =H29 -> 2020 | I47: =I29 -> 2021
A49: Beginning shareholder equity | E49: =D53 -> 1252039 | F49: =E53 -> 1318911.6 | G49: =F53 -> 1377665.7 | H49: =G53 -> 1433479.1 | I49: =H53 -> 1487479.4
A50: Plus: Net income | E50: ='Income Statement'!E19 -> 78673.607 | F50: ='Income Statement'!F19 -> 69122.555 | G50: ='Income Statement'!G19 -> 65662.738 | H50: ='Income Statement'!H19 -> 63529.759 | I50: ='Income Statement'!I19 -> 62524.844
A51: Less: Dividends | E51: =E7 -> -11801.041 | F51: =F7 -> -10368.383 | G51: =G7 -> -9849.4108 | H51: =H7 -> -9529.4638 | I51: =I7 -> -9378.7265
...

Sheet Fixed Asset Schedule
A1: =Assumptions!D6 -> Abercrombie & Fitch Co.
A3: Fixed Asset Schedule
A4: ="(Dollars in "&IF(Assumptions!$D$8=0,"Thousands","Millions")&")" -> (Dollars in Thousands)
B6: Cost | C6: Salvage | D6: Life | G6: ='Income Statement'!E6 -> 2017 | H6: ='Income Statement'!F6 -> 2018 | I6: ='Income Statement'!G6 -> 2019 | J6: ='Income Statement'!H6 -> 2020 | K6: ='Income Statement'!I6 -> 2021
A7: 2017 Beginning PPE (old) | B7: ='Balance Sheet'!D15 -> 824738 | C7: 0 | D7: 5 | F7: ='Balance Sheet'!E6 -> 2017 | G7: =IF(AND($F7<=G$6,$F7+$D7>G$6),SLN($B7,$B7*$C7,$D7),0) -> 164947.6 | H7: =IF(AND($F7<=H$6,$F7+$D7>H$6),SLN($B7,$B7*$C7,$D7),0) -> 164947.6 | I7: =IF(AND($F7<=I$6,$F7+$D7>I$6),SLN($B7,$B7*$C7,$D7),0) -> 164947.6 | J7: =IF(AND($F7<=J$6,$F7+$D7>J$6),SLN($B7,$B7*$C7,$D7),0) -> 164947.6 | K7: =IF(AND($F7<=K$6,$F7+$D7>K$6),SLN($B7,$B7*$C7,$D7),0) -> 164947.6
A8: 2017 CAPEX | B8: 140000 | C8: 0.05 | D8: 10 | F8: =G6 -> 2017 | G8: =IF(AND($F8<=G$6,$F8+$D8>G$6),SLN($B8,$B8*$C8,$D8),0) -> 13300 | H8: =IF(AND($F8<=H$6,$F8+$D8>H$6),SLN($B8,$B8*$C8,$D8),0) -> 13300 | I8: =IF(AND($F8<=I$6,$F8+$D8>I$6),SLN($B8,$B8*$C8,$D8),0) -> 13300 | J8: =IF(AND($F8<=J$6,$F8+$D8>J$6),SLN($B8,$B8*$C8,$D8),0) -> 13300 | K8: =IF(AND($F8<=K$6,$F8+$D8>K$6),SLN($B8,$B8*$C8,$D8),0) -> 13300
A9: 2018 CAPEX | B9: 135000 | C9: 0.05 | D9: 10 | F9: =H6 -> 2018 | G9: =IF(AND($F9<=G$6,$F9+$D9>G$6),SLN($B9,$B9*$C9,$D9),0) -> 0 | H9: =IF(AND($F9<=H$6,$F9+$D9>H$6),SLN($B9,$B9*$C9,$D9),0) -> 12825 | I9: =IF(AND($F9<=I$6,$F9+$D9>I$6),SLN($B9,$B9*$C9,$D9),0) -> 12825 | J9: =IF(AND($F9<=J$6,$F9+$D9>J$6),SLN($B9,$B9*$C9,$D9),0) -> 12825 | K9: =IF(AND($F9<=K$6,$F9+$D9>K$6),SLN($B9,$B9*$C9,$D9),0) -> 12825
A10: 2019 CAPEX | B10: 130000 | C10: 0.05 | D10: 15 | F10: =I6 -> 2019 | G10: =IF(AND($F10<=G$6,$F10+$D10>G$6),SLN($B10,$B10*$C10,$D10),0) -> 0 | H10: =IF(AND($F10<=H$6,$F10+$D10>H$6),SLN($B10,$B10*$C10,$D10),0) -> 0 | I10: =IF(AND($F10<=I$6,$F10+$D10>I$6),SLN($B10,$B10*$C10,$D10),0) -> 8233.3333 | J10: =IF(AND($F10<=J$6,$F10+$D10>J$6),SLN($B10,$B10*$C10,$D10),0) -> 8233.3333 | K10: =IF(AND($F10<=K$6,$F10+$D10>K$6),SLN($B10,$B10*$C10,$D10),0) -> 8233.3333
A11: 2020 CAPEX | B11: 130000 | C11: 0.05 | D11: 15 | F11: =J6 -> 2020 | G11: =IF(AND($F11<=G$6,$F11+$D11>G$6),SLN($B11,$B11*$C11,$D11),0) -> 0 | H11: =IF(AND($F11<=H$6,$F11+$D11>H$6),SLN($B11,$B11*$C11,$D11),0) -> 0 | I11: =IF(AND($F11<=I$6,$F11+$D11>I$6),SLN($B11,$B11*$C11,$D11),0) -> 0 | J11: =IF(AND($F11<=J$6,$F11+$D11>J$6),SLN($B11,$B11*$C11,$D11),0) -> 8233.3333 | K11: =IF(AND($F11<=K$6,$F11+$D11>K$6),SLN($B11,$B11*$C11,$D11),0) -> 8233.3333
A12: 2021 CAPEX | B12: 130000 | C12: 0.05 | D12: 15 | F12: =K6 -> 2021 | G12: =IF(AND($F12<=G$6,$F12+$D12>G$6),SLN($B12,$B12*$C12,$D12),0) -> 0 | H12: =IF(AND($F12<=H$6,$F12+$D12>H$6),SLN($B12,$B12*$C12,$D12),0) -> 0 | I12: =IF(AND($F12<=I$6,$F12+$D12>I$6),SLN($B12,$B12*$C12,$D12),0) -> 0 | J12: =IF(AND($F12<=J$6,$F12+$D12>J$6),SLN($B12,$B12*$C12,$D12),0) -> 0 | K12: =IF(AND($F12<=K$6,$F12+$D12>K$6),SLN($B12,$B12*$C12,$D12),0) -> 8233.3333
G13: =SUM(G7:G12) -> 178247.6 | H13: =SUM(H7:H12) -> 191072.6 | I13: =SUM(I7:I12) -> 199305.93 | J13: =SUM(J7:J12) -> 207539.27 | K13: =SUM(K7:K12) -> 215772.6
G17: =G6 -> 2017 | H17: =H6 -> 2018 | I17: =I6 -> 2019 | J17: =J6 -> 2020 | K17: =K6 -> 2021
E18: Beginning Balance - PPE | G18: =B7 -> 824738 | H18: =G21 -> 786490.4 | I18: =H21 -> 730417.8 | J18: =I21 -> 661111.87 | K18: =J21 -> 583572.6
E19: Add: CAPEX | G19: {=TRANSPOSE(B8:B12)} -> 140000 | H19: 135000 | I19: 130000 | J19: 130000 | K19: 130000
E20: Less: D&A - PPE | G20: =-G13 -> -178247.6 | H20: =-H13 -> -191072.6 | I20: =-I13 -> -199305.93 | J20: =-J13 -> -207539.27 | K20: =-K13 -> -215772.6
E21: Ending Balance - PPE | G21: =SUM(G18:G20) -> 786490.4 | H21: =SUM(H18:H20) -> 730417.8 | I21: =SUM(I18:I20) -> 661111.87 | J21: =SUM(J18:J20) -> 583572.6 | K21: =SUM(K18:K20) -> 497800

Sheet Valuation
A1: =Assumptions!D6 -> Abercrombie & Fitch Co.
A3: Valuation
A4: ="(Dollars in "&IF(Assumptions!$D$8=0,"Thousands","Millions")&" Except Per Share Data)" -> (Dollars in Thousands Except Per Share Data)
A6: Assumptions
A7: Basic shares outstanding | B7: =Assumptions!E79 -> 68100
A8: WACC | B8: =B30 -> 0.10388
A9: =A31 -> Terminal growth rate | B9: =B31 -> 0.01
A12: FCFF Calculation
C13: ='Income Statement'!E6 -> 2017 | D13: ='Income Statement'!F6 -> 2018 | E13: ='Income Statement'!G6 -> 2019 | F13: ='Income Statement'!H6 -> 2020 | G13: ='Income Statement'!I6 -> 2021
A14: EBIT | D14: ='Income Statement'!F14 -> 88872.571 | E14: ='Income Statement'!G14 -> 82038.964 | F14: ='Income Statement'!H14 -> 76619.079 | G14: ='Income Statement'!I14 -> 72648.121
A15: tax rate | D15: =Assumptions!F77 -> 0.21 | E15: =Assumptions!G77 -> 0.21 | F15: =Assumptions!H77 -> 0.21 | G15: =Assumptions!I77 -> 0.21
A16: NOPAT(EBIAT) | D16: =D14*(1-D15) -> 70209.331 | E16: =E14*(1-E15) -> 64810.781 | F16: =F14*(1-F15) -> 60529.073 | G16: =G14*(1-G15) -> 57392.016
A17: Depreciation & Amortization | D17: ='Fixed Asset Schedule'!H13 -> 191072.6 | E17: ='Fixed Asset Schedule'!I13 -> 199305.93 | F17: ='Fixed Asset Schedule'!J13 -> 207539.27 | G17: ='Fixed Asset Schedule'!K13 -> 215772.6
A18: CAPEX | D18: =-'Fixed Asset Schedule'!H19 -> -135000 | E18: =-'Fixed Asset Schedule'!I19 -> -130000 | F18: =-'Fixed Asset Schedule'!J19 -> -130000 | G18: =-'Fixed Asset Schedule'!K19 -> -130000
A19: Other CFO Adjustment | D19: =SUM(SCF!C11:C17) -> 14717.624 | E19: =SUM(SCF!D11:D17) -> -11603.529 | F19: =SUM(SCF!E11:E17) -> 2427.7156 | G19: =SUM(SCF!F11:F17) -> -158.60881
A20: Free Cash Flow to the Firm (FCFF) | D20: =SUM(D16:D19) -> 140999.55 | E20: =SUM(E16:E19) -> 122513.19 | F20: =SUM(F16:F19) -> 140496.05 | G20: =SUM(G16:G19) -> 143006.01
A21: Discount Period (as of 12/31/2017) | C21: =C13-2017 -> 0 | D21: =D13-2017 -> 1 | E21: =E13-2017 -> 2 | F21: =F13-2017 -> 3 | G21: =G13-2017 -> 4
A22: Present value of FCFF | C22: =C20/(1+$B$8)^C21 -> 0 | D22: =D20/(1+$B$8)^D21 -> 127730.87 | E22: =E20/(1+$B$8)^E21 -> 100540.05 | F22: =F20/(1+$B$8)^F21 -> 104447.62 | G22: =G20/(1+$B$8)^G21 -> 96308.988
A23: Terminal Value as of 12/31/2017 | G23: =B36 -> 1538518
A26: Cost of Capital (WACC) calculation
A27: Cost of equity | B27: 0.12
A28: Equity/(Debt+Equity) | B28: 0.792
A29: After-tax cost of debt | B29: 0.0425
A30: WACC | B30: =B27*B28+B29*(1-B28) -> 0.10388
A31: Terminal growth rate | B31: 0.01
A34: Perpetuity approach
A35: Terminal year FFCF | B35: =G20 -> 143006.01
A36: Terminal value | B36: =B35*(1+B9)/(B8-B9) -> 1538518
A37: Present value of Terminal value | B37: =B36/(1+B8)^G21 -> 1036132.1
A38: Present value of FFCF | B38: =SUM(C22:G22) -> 429027.53
A39: Enterprise value as of 12/31/2017 | B39: =B37+B38 -> 1465159.6
A42: Equity value per share
A43: Enterprise value as of 12/31/2017 | B43: =B39 -> 1465159.6
A44: Less: Net Debt as of 12/31/2017 | B44: =-(B45+B46) -> 511440.69
A45: Gross Debt | B45: ='Balance Sheet'!E27+'Balance Sheet'!E31+'Balance Sheet'!E32 -> 412992
A46: Less: Cash and equivalents | B46: =-'Balance Sheet'!E8 -> -924432.69
A47: Equity value as of 12/31/2017 | B47: =B43+B44 -> 1976600.3
A48: Basic shares outstanding | B48: =B7 -> 68100
A49: Value per share | B49: =B47/B48 -> 29.024967
A52: Sensitivity Table
...

Sheet Risk Tables
A1: =Assumptions!D6 -> Abercrombie & Fitch Co.
A5: Financial Risk and Operating Performance Assessment Criteria
A7: Financial Risk Assessment
B8: HIGH | C8: MEDIUM | D8: LOW | G8: Liquidity Cutoffs | H8: Risk | J8: Solvency Cutoffs | K8: Risk | M8: Payback Cutoffs | N8: Risk | P8: Coverage Cutoffs | Q8: Risk
A9: Liquidity | B9: Average of two ratios < 1.5 | C9: 1.5 < = Average of two ratios < 2.5 | D9: Average of two ratios > = 2.5 | G9: -1e+307 | H9: HIGH | J9: -1e+307 | K9: HIGH | M9: -1e+307 | N9: HIGH | P9: -1e+307 | Q9: HIGH
A10: Solvency | B10: Ratio < 10% | C10: 10% < = Ratio < 50% | D10: Ratio > = 50% | G10: =VALUE(_xlfn.TEXTBEFORE(C9," <")) -> 1.5 | H10: MEDIUM | J10: =VALUE(_xlfn.TEXTBEFORE(C10," <")) -> 0.1 | K10: MEDIUM | M10: =VALUE(_xlfn.TEXTBEFORE(C11," <")) -> 0.25 | N10: MEDIUM | P10: =VALUE(_xlfn.TEXTBEFORE(C12," <")) -> 3 | Q10: MEDIUM
A11: Payback | B11: Ratio < 25% | C11: 25% < = Ratio < 50% | D11: Ratio > = 50% | G11: =VALUE(_xlfn.TEXTAFTER(D9,"= ")) -> 2.5 | H11: LOW | J11: =VALUE(_xlfn.TEXTAFTER(D10,"= ")) -> 0.5 | K11: LOW | M11: =VALUE(_xlfn.TEXTAFTER(D11,"= ")) -> 0.5 | N11: LOW | P11: =VALUE(_xlfn.TEXTAFTER(D12,"= ")) -> 10 | Q11: LOW
A12: Coverage | B12: Ratio < 3 | C12: 3 < = Ratio < 10 | D12: Ratio > = 10
A15: Operating Performance Assessment
B16: WEAK | C16: AVERAGE | D16: STRONG | G16: Return on Equity Cutoffs | H16: Risk | J16: Revenue Growth Cutoffs | K16: Risk | M16: EBIT Margin Cutoffs | N16: Risk | P16: Net Margin Cutoffs | Q16: Risk
A17: Return on Equity | B17: Ratio < 8% | C17: 8% < = Ratio < 12% | D17: Ratio > = 12% | G17: -1e+307 | H17: WEAK | J17: -1e+307 | K17: WEAK | M17: -1e+307 | N17: WEAK | P17: -1e+307 | Q17: WEAK
A18: Revenue Growth | B18: Ratio < 2% | C18: 2% < = Ratio < 7% | D18: Ratio > = 7% | G18: =VALUE(_xlfn.TEXTBEFORE(C17," <")) -> 0.08 | H18: AVERAGE | J18: =VALUE(_xlfn.TEXTBEFORE(C18," <")) -> 0.02 | K18: AVERAGE | M18: =VALUE(_xlfn.TEXTBEFORE(C19," <")) -> 0.1 | N18: AVERAGE | P18: =VALUE(_xlfn.TEXTBEFORE(C20," <")) -> 0.05 | Q18: AVERAGE
A19: EBIT Margin | B19: Ratio < 10% | C19: 10% < = Ratio < 20% | D19: Ratio > = 20% | G19: =VALUE(_xlfn.TEXTAFTER(D17,"= ")) -> 0.12 | H19: STRONG | J19: =VALUE(_xlfn.TEXTAFTER(D18,"= ")) -> 0.07 | K19: STRONG | M19: =VALUE(_xlfn.TEXTAFTER(D19,"= ")) -> 0.2 | N19: STRONG | P19: =VALUE(_xlfn.TEXTAFTER(D20,"= ")) -> 0.15 | Q19: STRONG
A20: Net Margin | B20: Ratio < 5% | C20: 5% < = Ratio < 15% | D20: Ratio > = 15%

Sheet Rating Calculation
A1: =Assumptions!D6 -> Abercrombie & Fitch Co.
A4: Debt Rating Calculation
A6: Financial Risk | B6: ='Income Statement'!E6 -> 2017 | C6: ='Income Statement'!F6 -> 2018 | D6: ='Income Statement'!G6 -> 2019 | E6: ='Income Statement'!H6 -> 2020 | F6: ='Income Statement'!I6 -> 2021 | H6: Operating Risk | I6: =B6 -> 2017 | J6: =C6 -> 2018 | K6: =D6 -> 2019 | L6: =E6 -> 2020 | M6: =F6 -> 2021
A8: Liquidity | H8: Return on Equity
A9: Current Ratio | B9: ='Balance Sheet'!E12/'Balance Sheet'!E28 -> 3.1848625 | C9: ='Balance Sheet'!F12/'Balance Sheet'!F28 -> 2.9056759 | D9: ='Balance Sheet'!G12/'Balance Sheet'!G28 -> 3.441862 | E9: ='Balance Sheet'!H12/'Balance Sheet'!H28 -> 3.370824 | F9: ='Balance Sheet'!I12/'Balance Sheet'!I28 -> 3.83628 | H9: Net Income/Total Equity | I9: ='Income Statement'!E19/'Balance Sheet'!E39 -> 0.059650404 | J9: ='Income Statement'!F19/'Balance Sheet'!F39 -> 0.050173677 | K9: ='Income Statement'!G19/'Balance Sheet'!G39 -> 0.045806555 | L9: ='Income Statement'!H19/'Balance Sheet'!H39 -> 0.042709674 | M9: ='Income Statement'!I19/'Balance Sheet'!I39 -> 0.040584064
A10: Quick Ratio | B10: =('Balance Sheet'!E8+'Balance Sheet'!E9)/'Balance Sheet'!E28 -> 2.1102534 | C10: =('Balance Sheet'!F8+'Balance Sheet'!F9)/'Balance Sheet'!F28 -> 2.0040488 | D10: =('Balance Sheet'!G8+'Balance Sheet'!G9)/'Balance Sheet'!G28 -> 2.4001407 | E10: =('Balance Sheet'!H8+'Balance Sheet'!H9)/'Balance Sheet'!H28 -> 2.4219538 | F10: =('Balance Sheet'!I8+'Balance Sheet'!I9)/'Balance Sheet'!I28 -> 2.7963364 | H10: ROE Performance (STRONG, AVERAGE, or WEAK) | I10: =VLOOKUP(I$9,'Risk Tables'!$G$17:$H$19,2,1) -> WEAK | J10: =VLOOKUP(J$9,'Risk Tables'!$G$17:$H$19,2,1) -> WEAK | K10: =VLOOKUP(K$9,'Risk Tables'!$G$17:$H$19,2,1) -> WEAK | L10: =VLOOKUP(L$9,'Risk Tables'!$G$17:$H$19,2,1) -> WEAK | M10: =VLOOKUP(M$9,'Risk Tables'!$G$17:$H$19,2,1) -> WEAK
A11: Average of Two Ratios | B11: =AVERAGE(B9,B10) -> 2.6475579 | C11: =AVERAGE(C9,C10) -> 2.4548623 | D11: =AVERAGE(D9,D10) -> 2.9210014 | E11: =AVERAGE(E9,E10) -> 2.8963889 | F11: =AVERAGE(F9,F10) -> 3.3163082
A12: Liquidity Risk (LOW, MEDIUM, or HIGH) | B12: =VLOOKUP(B$11,'Risk Tables'!$G$9:$H$11,2,1) -> LOW | C12: =VLOOKUP(C$11,'Risk Tables'!$G$9:$H$11,2,1) -> MEDIUM | D12: =VLOOKUP(D$11,'Risk Tables'!$G$9:$H$11,2,1) -> LOW | E12: =VLOOKUP(E$11,'Risk Tables'!$G$9:$H$11,2,1) -> LOW | F12: =VLOOKUP(F$11,'Risk Tables'!$G$9:$H$11,2,1) -> LOW
A15: Solvency | H15: Growth
A16: Equity/Total Capital (Debt+Equity) | B16: ='Balance Sheet'!E39/('Balance Sheet'!E27+'Balance Sheet'!E31+'Balance Sheet'!E32+'Balance Sheet'!E39) -> 0.76153869 | C16: ='Balance Sheet'!F39/('Balance Sheet'!F27+'Balance Sheet'!F31+'Balance Sheet'!F32+'Balance Sheet'!F39) -> 0.76936296 | D16: ='Balance Sheet'!G39/('Balance Sheet'!G27+'Balance Sheet'!G31+'Balance Sheet'!G32+'Balance Sheet'!G39) -> 0.80627425 | E16: ='Balance Sheet'!H39/('Balance Sheet'!H27+'Balance Sheet'!H31+'Balance Sheet'!H32+'Balance Sheet'!H39) -> 0.81198483 | F16: ='Balance Sheet'!I39/('Balance Sheet'!I27+'Balance Sheet'!I31+'Balance Sheet'!I32+'Balance Sheet'!I39) -> 0.83955436 | H16: Revenue Growth | I16: =Assumptions!E68 -> -0.01 | J16: =Assumptions!F68 -> 0 | K16: =Assumptions!G68 -> 0.005 | L16: =Assumptions!H68 -> 0.01 | M16: =Assumptions!I68 -> 0.015
A17: Solvency Risk (LOW, MEDIUM, or HIGH) | B17: =VLOOKUP(B$16,'Risk Tables'!$J$9:$K$11,2,1) -> LOW | C17: =VLOOKUP(C$16,'Risk Tables'!$J$9:$K$11,2,1) -> LOW | D17: =VLOOKUP(D$16,'Risk Tables'!$J$9:$K$11,2,1) -> LOW | E17: =VLOOKUP(E$16,'Risk Tables'!$J$9:$K$11,2,1) -> LOW | F17: =VLOOKUP(F$16,'Risk Tables'!$J$9:$K$11,2,1) -> LOW | H17: Growth Performance (STRONG, AVERAGE, or WEAK) | I17: =VLOOKUP(I$16,'Risk Tables'!$J$17:$K$19,2,1) -> WEAK | J17: =VLOOKUP(J$16,'Risk Tables'!$J$17:$K$19,2,1) -> WEAK | K17: =VLOOKUP(K$16,'Risk Tables'!$J$17:$K$19,2,1) -> WEAK | L17: =VLOOKUP(L$16,'Risk Tables'!$J$17:$K$19,2,1) -> WEAK | M17: =VLOOKUP(M$16,'Risk Tables'!$J$17:$K$19,2,1) -> WEAK
A20: Debt Payback | H20: EBIT Margin
A21: EBITDA/Debt | B21: =('Income Statement'!E14-'Income Statement'!E12)/('Balance Sheet'!E27+'Balance Sheet'!E31+'Balance Sheet'!E32) -> 0.67784647 | C21: =('Income Statement'!F14-'Income Statement'!F12)/('Balance Sheet'!F27+'Balance Sheet'!F31+'Balance Sheet'!F32) -> 0.67784647 | D21: =('Income Statement'!G14-'Income Statement'!G12)/('Balance Sheet'!G27+'Balance Sheet'!G31+'Balance Sheet'!G32) -> 0.81685151 | E21: =('Income Statement'!H14-'Income Statement'!H12)/('Balance Sheet'!H27+'Balance Sheet'!H31+'Balance Sheet'!H32) -> 0.82502002 | F21: =('Income Statement'!I14-'Income Statement'!I12)/('Balance Sheet'!I27+'Balance Sheet'!I31+'Balance Sheet'!I32) -> 0.97960344 | H21: EBIT/Revenue | I21: ='Income Statement'!E14/'Income Statement'!E7 -> 0.030878523 | J21: ='Income Statement'!F14/'Income Statement'!F7 -> 0.026984457 | K21: ='Income Statement'!G14/'Income Statement'!G7 -> 0.024785635 | L21: ='Income Statement'!H14/'Income Statement'!H7 -> 0.022918988 | M21: ='Income Statement'!I14/'Income Statement'!I7 -> 0.021410009
A22: Payback Risk (LOW, MEDIUM, or HIGH) | B22: =VLOOKUP(B$21,'Risk Tables'!$M$9:$N$11,2,1) -> LOW | C22: =VLOOKUP(C$21,'Risk Tables'!$M$9:$N$11,2,1) -> LOW | D22: =VLOOKUP(D$21,'Risk Tables'!$M$9:$N$11,2,1) -> LOW | E22: =VLOOKUP(E$21,'Risk Tables'!$M$9:$N$11,2,1) -> LOW | F22: =VLOOKUP(F$21,'Risk Tables'!$M$9:$N$11,2,1) -> LOW | H22: EBIT Margin Performance (STRONG, AVERAGE, or WEAK) | I22: =VLOOKUP(I$21,'Risk Tables'!$M$17:$N$19,2,1) -> WEAK | J22: =VLOOKUP(J$21,'Risk Tables'!$M$17:$N$19,2,1) -> WEAK | K22: =VLOOKUP(K$21,'Risk Tables'!$M$17:$N$19,2,1) -> WEAK | L22: =VLOOKUP(L$21,'Risk Tables'!$M$17:$N$19,2,1) -> WEAK | M22: =VLOOKUP(M$21,'Risk Tables'!$M$17:$N$19,2,1) -> WEAK
A25: Interest Coverage | H25: Net Margin
A26: EBITDA/Interest Expense | B26: =('Income Statement'!E14-'Income Statement'!E12)/(-'Income Statement'!E16) -> 21.292025 | C26: =('Income Statement'!F14-'Income Statement'!F12)/(-'Income Statement'!F16) -> 17.425359 | D26: =('Income Statement'!G14-'Income Statement'!G12)/(-'Income Statement'!G16) -> 19.097821 | E26: =('Income Statement'!H14-'Income Statement'!H12)/(-'Income Statement'!H16) -> 21.208741 | F26: =('Income Statement'!I14-'Income Statement'!I12)/(-'Income Statement'!I16) -> 23.211681 | H26: NI/Revenue | I26: ='Income Statement'!E19/'Income Statement'!E7 -> 0.023887737 | J26: ='Income Statement'!F19/'Income Statement'!F7 -> 0.020987743 | K26: ='Income Statement'!G19/'Income Statement'!G7 -> 0.019838045 | L26: ='Income Statement'!H19/'Income Statement'!H7 -> 0.019003593 | M26: ='Income Statement'!I19/'Income Statement'!I7 -> 0.018426595
A27: Coverage Risk (LOW, MEDIUM, or HIGH) | B27: =VLOOKUP(B$26,'Risk Tables'!$P$9:$Q$11,2,1) -> LOW | C27: =VLOOKUP(C$26,'Risk Tables'!$P$9:$Q$11,2,1) -> LOW | D27: =VLOOKUP(D$26,'Risk Tables'!$P$9:$Q$11,2,1) -> LOW | E27: =VLOOKUP(E$26,'Risk Tables'!$P$9:$Q$11,2,1) -> LOW | F27: =VLOOKUP(F$26,'Risk Tables'!$P$9:$Q$11,2,1) -> LOW | H27: Net Margin Performance (STRONG, AVERAGE, or WEAK) | I27: =VLOOKUP(I$26,'Risk Tables'!$P$17:$Q$19,2,1) -> WEAK | J27: =VLOOKUP(J$26,'Risk Tables'!$P$17:$Q$19,2,1) -> WEAK | K27: =VLOOKUP(K$26,'Risk Tables'!$P$17:$Q$19,2,1) -> WEAK | L27: =VLOOKUP(L$26,'Risk Tables'!$P$17:$Q$19,2,1) -> WEAK | M27: =VLOOKUP(M$26,'Risk Tables'!$P$17:$Q$19,2,1) -> WEAK
A29: Number of LOW risk categories | B29: =COUNTIF(B$12,"LOW")+COUNTIF(B$17,"LOW")+COUNTIF(B$22,"LOW")+COUNTIF(B$27,"LOW") -> 4 | C29: =COUNTIF(C$12,"LOW")+COUNTIF(C$17,"LOW")+COUNTIF(C$22,"LOW")+COUNTIF(C$27,"LOW") -> 3 | D29: =COUNTIF(D$12,"LOW")+COUNTIF(D$17,"LOW")+COUNTIF(D$22,"LOW")+COUNTIF(D$27,"LOW") -> 4 | E29: =COUNTIF(E$12,"LOW")+COUNTIF(E$17,"LOW")+COUNTIF(E$22,"LOW")+COUNTIF(E$27,"LOW") -> 4 | F29: =COUNTIF(F$12,"LOW")+COUNTIF(F$17,"LOW")+COUNTIF(F$22,"LOW")+COUNTIF(F$27,"LOW") -> 4 | H29: Number of STRONG performance categories | I29: =COUNTIF(I$10,"STRONG")+COUNTIF(I$17,"STRONG")+COUNTIF(I$22,"STRONG")+COUNTIF(I$27,"STRONG") -> 0 | J29: =COUNTIF(J$10,"STRONG")+COUNTIF(J$17,"STRONG")+COUNTIF(J$22,"STRONG")+COUNTIF(J$27,"STRONG") -> 0 | K29: =COUNTIF(K$10,"STRONG")+COUNTIF(K$17,"STRONG")+COUNTIF(K$22,"STRONG")+COUNTIF(K$27,"STRONG") -> 0 | L29: =COUNTIF(L$10,"STRONG")+COUNTIF(L$17,"STRONG")+COUNTIF(L$22,"STRONG")+COUNTIF(L$27,"STRONG") -> 0 | M29: =COUNTIF(M$10,"STRONG")+COUNTIF(M$17,"STRONG")+COUNTIF(M$22,"STRONG")+COUNTIF(M$27,"STRONG") -> 0
A30: Number of MEDIUM risk categories | B30: =COUNTIF(B$12,"MEDIUM")+COUNTIF(B$17,"MEDIUM")+COUNTIF(B$22,"MEDIUM")+COUNTIF(B$27,"MEDIUM") -> 0 | C30: =COUNTIF(C$12,"MEDIUM")+COUNTIF(C$17,"MEDIUM")+COUNTIF(C$22,"MEDIUM")+COUNTIF(C$27,"MEDIUM") -> 1 | D30: =COUNTIF(D$12,"MEDIUM")+COUNTIF(D$17,"MEDIUM")+COUNTIF(D$22,"MEDIUM")+COUNTIF(D$27,"MEDIUM") -> 0 | E30: =COUNTIF(E$12,"MEDIUM")+COUNTIF(E$17,"MEDIUM")+COUNTIF(E$22,"MEDIUM")+COUNTIF(E$27,"MEDIUM") -> 0 | F30: =COUNTIF(F$12,"MEDIUM")+COUNTIF(F$17,"MEDIUM")+COUNTIF(F$22,"MEDIUM")+COUNTIF(F$27,"MEDIUM") -> 0 | H30: Number of AVERAGE performance categories | I30: =COUNTIF(I$10,"AVERAGE")+COUNTIF(I$17,"AVERAGE")+COUNTIF(I$22,"AVERAGE")+COUNTIF(I$27,"AVERAGE") -> 0 | J30: =COUNTIF(J$10,"AVERAGE")+COUNTIF(J$17,"AVERAGE")+COUNTIF(J$22,"AVERAGE")+COUNTIF(J$27,"AVERAGE") -> 0 | K30: =COUNTIF(K$10,"AVERAGE")+COUNTIF(K$17,"AVERAGE")+COUNTIF(K$22,"AVERAGE")+COUNTIF(K$27,"AVERAGE") -> 0 | L30: =COUNTIF(L$10,"AVERAGE")+COUNTIF(L$17,"AVERAGE")+COUNTIF(L$22,"AVERAGE")+COUNTIF(L$27,"AVERAGE") -> 0 | M30: =COUNTIF(M$10,"AVERAGE")+COUNTIF(M$17,"AVERAGE")+COUNTIF(M$22,"AVERAGE")+COUNTIF(M$27,"AVERAGE") -> 0
A31: Number of HIGH risk categories | B31: =COUNTIF(B$12,"HIGH")+COUNTIF(B$17,"HIGH")+COUNTIF(B$22,"HIGH")+COUNTIF(B$27,"HIGH") -> 0 | C31: =COUNTIF(C$12,"HIGH")+COUNTIF(C$17,"HIGH")+COUNTIF(C$22,"HIGH")+COUNTIF(C$27,"HIGH") -> 0 | D31: =COUNTIF(D$12,"HIGH")+COUNTIF(D$17,"HIGH")+COUNTIF(D$22,"HIGH")+COUNTIF(D$27,"HIGH") -> 0 | E31: =COUNTIF(E$12,"HIGH")+COUNTIF(E$17,"HIGH")+COUNTIF(E$22,"HIGH")+COUNTIF(E$27,"HIGH") -> 0 | F31: =COUNTIF(F$12,"HIGH")+COUNTIF(F$17,"HIGH")+COUNTIF(F$22,"HIGH")+COUNTIF(F$27,"HIGH") -> 0 | H31: Number of WEAK performance categories | I31: =COUNTIF(I$10,"WEAK")+COUNTIF(I$17,"WEAK")+COUNTIF(I$22,"WEAK")+COUNTIF(I$27,"WEAK") -> 4 | J31: =COUNTIF(J$10,"WEAK")+COUNTIF(J$17,"WEAK")+COUNTIF(J$22,"WEAK")+COUNTIF(J$27,"WEAK") -> 4 | K31: =COUNTIF(K$10,"WEAK")+COUNTIF(K$17,"WEAK")+COUNTIF(K$22,"WEAK")+COUNTIF(K$27,"WEAK") -> 4 | L31: =COUNTIF(L$10,"WEAK")+COUNTIF(L$17,"WEAK")+COUNTIF(L$22,"WEAK")+COUNTIF(L$27,"WEAK") -> 4 | M31: =COUNTIF(M$10,"WEAK")+COUNTIF(M$17,"WEAK")+COUNTIF(M$22,"WEAK")+COUNTIF(M$27,"WEAK") -> 4
A33: Weight for LOW risk categories | B33: 1 | C33: 1 | D33: 1 | E33: 1 | F33: 1 | H33: Weight for STRONG performance categories | I33: 1 | J33: 1 | K33: 1 | L33: 1 | M33: 1
A34: Weight for MEDIUM risk categories | B34: 2 | C34: 2 | D34: 2 | E34: 2 | F34: 2 | H34: Weight for AVERAGE performance categories | I34: 2 | J34: 2 | K34: 2 | L34: 2 | M34: 2
A35: Weight for HIGH risk categories | B35: 5 | C35: 5 | D35: 5 | E35: 5 | F35: 5 | H35: Weight for WEAK performance categories | I35: 5 | J35: 5 | K35: 5 | L35: 5 | M35: 5
A37: Financial Risk Summary (Lower = Low Risk) | B37: =SUMPRODUCT(B$29:B$31,B$33:B$35) -> 4 | C37: =SUMPRODUCT(C$29:C$31,C$33:C$35) -> 5 | D37: =SUMPRODUCT(D$29:D$31,D$33:D$35) -> 4 | E37: =SUMPRODUCT(E$29:E$31,E$33:E$35) -> 4 | F37: =SUMPRODUCT(F$29:F$31,F$33:F$35) -> 4 | H37: Operating Risk Summary (Lower = Lower Risk) | I37: =SUMPRODUCT(I$29:I$31,I$33:I$35) -> 20 | J37: =SUMPRODUCT(J$29:J$31,J$33:J$35) -> 20 | K37: =SUMPRODUCT(K$29:K$31,K$33:K$35) -> 20 | L37: =SUMPRODUCT(L$29:L$31,L$33:L$35) -> 20 | M37: =SUMPRODUCT(M$29:M$31,M$33:M$35) -> 20
A40: Weight given to Financial Risk Summary (%) | B40: 80
A43: Credit Risk Summary Calculation
A44: Weight given to Financial Risk Summary | B44: =$B$40/100 -> 0.8 | C44: =$B$40/100 -> 0.8 | D44: =$B$40/100 -> 0.8 | E44: =$B$40/100 -> 0.8 | F44: =$B$40/100 -> 0.8
A45: Weight given to Operating Risk Summary | B45: =1-B44 -> 0.2 | C45: =1-C44 -> 0.2 | D45: =1-D44 -> 0.2 | E45: =1-E44 -> 0.2 | F45: =1-F44 -> 0.2
A46: Overall Credit Risk Summary | B46: =ROUNDUP(B$37*B$44+I$37*B$45,0) -> 8 | C46: =ROUNDUP(C$37*C$44+J$37*C$45,0) -> 8 | D46: =ROUNDUP(D$37*D$44+K$37*D$45,0) -> 8 | E46: =ROUNDUP(E$37*E$44+L$37*E$45,0) -> 8 | F46: =ROUNDUP(F$37*F$44+M$37*F$45,0) -> 8
A48: Debt Rating | B48: =IF(B$46<17,VLOOKUP(B$46,'Ratings and Rates'!$A$6:$D$20,3,0),'Ratings and Rates'!$C$7) -> A- | C48: =IF(C$46<17,VLOOKUP(C$46,'Ratings and Rates'!$A$6:$D$20,3,0),'Ratings and Rates'!$C$7) -> A- | D48: =IF(D$46<17,VLOOKUP(D$46,'Ratings and Rates'!$A$6:$D$20,3,0),'Ratings and Rates'!$C$7) -> A- | E48: =IF(E$46<17,VLOOKUP(E$46,'Ratings and Rates'!$A$6:$D$20,3,0),'Ratings and Rates'!$C$7) -> A- | F48: =IF(F$46<17,VLOOKUP(F$46,'Ratings and Rates'!$A$6:$D$20,3,0),'Ratings and Rates'!$C$7) -> A-

Sheet Ratings and Rates
A1: =Assumptions!D6 -> Abercrombie & Fitch Co.
A4: Credit Risk Ratings by Credit Risk Summary Measure
A6: Credit Risk Summary | C6: Rating
A7: 17 | B7: or higher | C7: D
A8: 16 | C8: C
A9: 15 | C9: CC
A10: 14 | C10: CCC
A11: 13 | C11: B-
A12: 12 | C12: B
A13: 11 | C13: B+
A14: 10 | C14: BB
A15: 9 | C15: BBB
A16: 8 | C16: A-
A17: 7 | C17: A
A18: 6 | C18: A+
A19: 5 | C19: AA
A20: 4 | C20: AAA
